Workbook

Sheet Quick Offers
B1: FULL REHAB | E1: FILL THIS OUT
B3: 70% of ARV | C3: =F3*0.7 -> 210000 | E3: ARV (after repair value) | F3: =K3 -> 300000 | G3: average of 3 comps | H3: 300000 | I3: 300000 | J3: 300000 | K3: =AVERAGE(H3:J3) -> 300000
B4: Assignment Fee | C4: -10000 | E4: Square Footage | F4: 2000
B5: All In Max Limit | C5: =sum(C3:C4) -> 200000 | E5: Full Rehab | F5: 150 | G5: per squre foot cost
B6: Repair Costs | C6: =-F4*F5 -> -300000 | E6: Medium Rehab | F6: 100 | G6: per squre foot cost
B7: Offer | C7: =sum(C5:C6) -> -100000 | E7: Light Rehab | F7: 60 | G7: per squre foot cost
B8: % of ARV | C8: =C7/F3 -> -0.33333333
D9: https://meet.google.com/qpi-ibwe-vzs
B10: MEDIUM REHAB
B12: 70% of ARV | C12: =F3*0.7 -> 210000
B13: Assignment Fee | C13: -10000 | E13: Value | F13: Desired Outcome | G13: Probability of Sale | H13: / | I13: Time (Months) | J13: Effort | K13: Value
B14: All In Max Limit | C14: =sum(C12:C13) -> 200000 | E14: Where they want | F14: =F3 -> 300000 | G14: 0.6 | I14: 1 | J14: 1 | K14: =F14*G14/(I14*J14) -> 180000
B15: Repair Costs | C15: =-F4*F6 -> -200000 | E15: Where they are | F15: =F3 -> 300000 | G15: 1 | I15: 5 | J15: 5 | K15: =F15*G15/(I15*J15) -> 12000
B16: Offer | C16: =sum(C14:C15) -> 0 | K16: =K14-K15 -> 168000
B17: % of ARV | C17: =C16/F3 -> 0
B19: LIGHT REHAB
B21: 70% of ARV | C21: =F3*0.7 -> 210000
B22: Assignment Fee | C22: -10000
B23: All In Max Limit | C23: =sum(C21:C22) -> 200000
B24: Repair Costs | C24: =-F4*F7 -> -120000
B25: Offer | C25: =sum(C23:C24) -> 80000
B26: % of ARV | C26: =C25/F3 -> 0.26666667

Sheet Aquisitions Deal Analyzer
B2: PROPERTY INFORMATION
B3: Property Address: | M3: 70% of ARV | N3: =E13*0.7 -> 210000
B4: Total Square Footage: | M4: Assignment Fee | N4: -10000
B5: # of Units | M5: All In Max Limit | N5: =sum(N3:N4) -> 200000
B6: Occupied? | M6: Repair Costs | N6: =-E12 -> -20050
M7: Offer | N7: =sum(N5:N6) -> 179950
B8: PROPERTY VALUES/PRICING | G8: DEAL SUMMARY & POTENTIAL PROFIT | M8: % of ARV | N8: =N7/E13 -> 0.59983333
B9: Estimated Hold Time months : | E9: 4
B10: Current "As-Is" Value: | E10: 200000 | G10: Total Financing Costs: | J10: =E32 -> 15333.333 | M10: ROI
B11: Purchase Price: | E11: 200000 | G11: Total Holding Costs | J11: =J32 -> 7633.3333 | M11: Cash Invested | N11: =J10+J11 -> 22966.667
B12: Estimated Repair Costs: | E12: 20050 | G12: Total Buying Transaction Costs: | J12: =sum(F37:F39) -> 4500 | M12: Cash Return | N12: =J14 -> 44453.333
B13: After Repair Value: | E13: 300000 | G13: Total Selling Transaction Costs: | J13: =sum(F42:F49) -> 8030 | M13: ROI on Cash | N13: =N12/N11 -> 1.9355588
B14: PURCHSE AND REPAIR COSTS: | E14: =-sum(E11:F12) -> -220050 | G14: ESTIMATED NET PROFIT: | J14: =E13-(E11+E12+J10+J11+J12+J13) -> 44453.333 | M14: Time to Return | N14: =CONCATENATE(E9," Months") -> 4 Months
B17: FINANCING PROJECTION | G17: HOLDING COSTS
E18: Rate | F18: Amount Paid | J18: Monthly | K18: Annualized
B19: First Mortgage / Lien Amount: | E19: 200000 | G19: Property Taxes | J19: 0.0875 | K19: =((J19*E10)/12)*E9 -> 5833.3333
B20: First Mortgage Points: | E20: 0.03 | F20: =E20*$E$19 -> 6000 | G20: HOA & Condo Fees | J20: 0 | K20: =J20*E9 -> 0
B21: First Mortgage Interest: | E21: 0 | F21: =E21*E19*E9 -> 0 | G21: Insurance Costs | J21: 100 | K21: =J21*$E$9 -> 400
B22: First Mortgage Monthly Interest Only Payment: | E22: =0.14/12 -> 0.011666667 | F22: =E22*E19*E9 -> 9333.3333 | G22: Utilities | J22: 0 | K22: =J22*$E$9 -> 0
B23: Second Mortgage / Lien Amount: | E23: 0 | G23: Gas | J23: 150 | K23: =J23*$E$9 -> 600
B24: Second Mortgage Points: | E24: 0.1 | F24: =E24*$E$23 -> 0 | G24: Water | J24: 100 | K24: =J24*$E$9 -> 400
B25: Second Mortgage Interest: | E25: 0 | F25: =E25*$E$23 -> 0 | G25: Electricity | J25: 100 | K25: =J25*$E$9 -> 400
B26: Second Mortgage Monthly Interest Only Payment: | E26: 0 | F26: =E26*$E$23*E9 -> 0 | G26: Miscellaneous | K26: =J26*E9 -> 0
B27: Misc. Mortgage / Lien Amount: | F27: 0 | G27: Total Maintenance Costs | J27: =sum(K19:K26) -> 7633.3333
B28: Misc. Mortgage Points: | F28: 0 | G28: Miscellaneous Holding Costs | K28: =$E$9*J28 -> 0
B29: Misc. Mortgage Interest: | F29: 0 | G29: Miscellaneous Holding Costs | K29: =$E$9*J29 -> 0
B30: Misc. Mortgage Monthly Interest Only Payment: | F30: 0 | G30: Miscellaneous Holding Costs | K30: =$E$9*J30 -> 0
B31: Miscellaneous Financing Costs: | F31: 0 | G31: Miscellaneous Holding Costs | K31: =$E$9*J31 -> 0
B32: TOTAL FINANCING COSTS: | E32: =sum(F19:F31) -> 15333.333 | G32: TOTAL HOLDING COSTS: | J32: =sum(K19:K31) -> 7633.3333
B35: BUYING TRANSACTION COSTS | G35: NOTES
E36: % of Price | F36: Total
B37: Escrow / Attorney Fees | E37: 0.005 | F37: =E37*$E$13 -> 1500 | G37: Expected ROI in Delayed Draw Scenario | I37: Cash to Cover Delayed Draw | J37: Actual Delayed Draw ROI
B38: Title Insurance / Search Costs | E38: 0.01 | F38: =E38*$E$13 -> 3000
B39: Miscellaneous Buying Costs | E39: 0 | F39: =E39*$E$13 -> 0 | G39: Cash Invested | H39: =J10+J11 -> 22966.667 | I39: =-if(min('Delayed Draw Cash Flow'!H6:H41)<0,min('Delayed Draw Cash Flow'!H6:H41),0) -> 3246.875 | J39: =Sum(H39:I39) -> 26213.542
B40: SELLING TRANSACTION COSTS | G40: Cash Return | H40: =J14 -> 44453.333 | J40: =H40 -> 44453.333
E41: % of Price | F41: Total | G41: ROI on Cash | H41: =H40/H39 -> 1.9355588 | J41: =J40/J39 -> 1.6958156
B42: Escrow / Attorney Fees | E42: 0.005 | F42: =E42*$E$13 -> 1500 | G42: Time to Return | H42: =CONCATENATE(E9," Months") -> 4 Months | J42: =CONCATENATE(E9," Months") -> 4 Months
B43: Selling Recording Fees | E43: 0.0025 | F43: =E43*$E$11 -> 500
B44: Realtor Fees | E44: 0.03 | F44: =E44*$E$11 -> 6000 | G44: Expected ROI in Up Front Draw Scenario | I44: Cash to Cover Up Front Draw | J44: Actual Upfront Draw ROI
B45: Transfer & Conveyance Fees | E45: 0.0001 | F45: =E45*$E$13 -> 30
...

Sheet Delayed Draw Cash Flow
A1: DELAYED DRAW CASH FLOW SCHEDULE | K1: COSTS | L1: Construction Costs | M1: Purchase Price | N1: First Mortgage Points: | O1: First Mortgage Interest: | P1: First Mortgage Monthly Interest Only Payment: | Q1: Property Taxes | R1: HOA & Condo Fees | S1: Insurance Costs | T1: Utilities | X1: Buying Transaction Costs | AA1: Selling Transaction Costs | AF1: Staging Costs | AG1: Marketing Costs | AH1: Miscellaneous Selling Costs
A2: THE NUMBERS IN BLUE ARE AUTOMATICALLY CALCULATED. THE BOXES HIGHLIGHTED IN YELLOW ARE MEANT FOR YOU TO FILL OUT! | T2: Gas | U2: Water | V2: Electricity | W2: Miscellaneous | X2: Escrow / Attorney Fees | Y2: Title Insurance/Search Costs | Z2: Miscellaneous Buying Costs | AA2: Escrow / Attorney Fees | AB2: Selling Recording Fees | AC2: Realtor Fees | AD2: Transfer & Conveyance Fees | AE2: Home Warranty
B3: Net Cash In---> | C3: =sum(D6:D43) -> 300000 | F3: Duration Weeks | G3: Beginning Cash Balance ---> | H3: ='Aquisitions Deal Analyzer'!H39 -> 22966.667 | I3: Net Cash Out Below | K3: Estimated Total Costs | L3: ='Aquisitions Deal Analyzer'!E12 -> 20050 | M3: ='Aquisitions Deal Analyzer'!E11 -> 200000 | N3: ='Aquisitions Deal Analyzer'!F20 -> 6000 | O3: ='Aquisitions Deal Analyzer'!F21 -> 0 | P3: ='Aquisitions Deal Analyzer'!F22 -> 9333.3333 | Q3: ='Aquisitions Deal Analyzer'!K19 -> 5833.3333 | R3: ='Aquisitions Deal Analyzer'!K20 -> 0 | S3: ='Aquisitions Deal Analyzer'!K21 -> 400 | T3: ='Aquisitions Deal Analyzer'!K23 -> 600 | U3: ='Aquisitions Deal Analyzer'!K24 -> 400 | V3: ='Aquisitions Deal Analyzer'!K25 -> 400 | W3: ='Aquisitions Deal Analyzer'!K26 -> 0 | X3: ='Aquisitions Deal Analyzer'!F37 -> 1500 | Y3: ='Aquisitions Deal Analyzer'!F38 -> 3000 | Z3: ='Aquisitions Deal Analyzer'!F39 -> 0 | AA3: ='Aquisitions Deal Analyzer'!F42 -> 1500 | AB3: ='Aquisitions Deal Analyzer'!F43 -> 500 | AC3: ='Aquisitions Deal Analyzer'!F44 -> 6000 | AD3: ='Aquisitions Deal Analyzer'!F45 -> 30 | AE3: ='Aquisitions Deal Analyzer'!F46 -> 0 | AF3: ='Aquisitions Deal Analyzer'!F47 -> 0 | AG3: ='Aquisitions Deal Analyzer'!F48 -> 0 | AH3: ='Aquisitions Deal Analyzer'!F49 -> 0
F4: ='Aquisitions Deal Analyzer'!E9*4 -> 16 | I4: =sum(I6:I41) -> 255546.67 | K4: Frequency | L4: Weekly | M4: One Time | N4: One Time | O4: Monthly | P4: Monthly | Q4: One Time | R4: One Time | S4: Monthly | T4: Monthly | U4: Monthly | V4: Monthly | W4: Monthly | X4: One Time | Y4: One Time | Z4: One Time | AA4: One Time | AB4: One Time | AC4: One Time | AD4: One Time | AE4: One Time | AF4: One Time | AG4: One Time | AH4: One Time
B5: Cash In Source | C5: Week | D5: Amount | F5: Week | G5: Cash In to the Project During this Week | H5: Balance @ End of Week | I5: Expenses Required | K5: Week
B6: Lender Purchase Loan | C6: 1 | D6: ='Aquisitions Deal Analyzer'!E11 -> 200000 | F6: 1 | G6: =sumif($C$6:$C44,F6,$D$6:$D44) -> 200000 | H6: =H4+H3-I6+G6 -> 2596.875 | I6: =sum(L6:AH6) -> 220369.79 | K6: 1 | L6: =L3/(F4) -> 1253.125 | M6: =M3 -> 200000 | N6: =N3 -> 6000 | O6: =O3/('Aquisitions Deal Analyzer'!$E$9) -> 0 | P6: =P3/('Aquisitions Deal Analyzer'!$E$9) -> 2333.3333 | Q6: =Q3 -> 5833.3333 | R6: =R3 -> 0 | S6: =S3/('Aquisitions Deal Analyzer'!$E$9) -> 100 | T6: =T3/('Aquisitions Deal Analyzer'!$E$9) -> 150 | U6: =U3/('Aquisitions Deal Analyzer'!$E$9) -> 100 | V6: =V3/('Aquisitions Deal Analyzer'!$E$9) -> 100 | W6: =W3/('Aquisitions Deal Analyzer'!$E$9) -> 0 | X6: =X3 -> 1500 | Y6: =Y3 -> 3000 | Z6: =Z3 -> 0 | AA6: =if($K6=$F$4,AA$3,0) -> 0 | AB6: =if($K6=$F$4,AB$3,0) -> 0 | AC6: =if($K6=$F$4,AC$3,0) -> 0 | AD6: =if($K6=$F$4,AD$3,0) -> 0 | AE6: =if($K6=$F$4,AE$3,0) -> 0 | AF6: =if($K6=$F$4,AF$3,0) -> 0 | AG6: =if($K6=$F$4,AG$3,0) -> 0 | AH6: =if($K6=$F$4,AH$3,0) -> 0
B7: Lender Draw 1 at 25% | C7: =F4*E7 -> 4 | D7: ='Aquisitions Deal Analyzer'!$E$12/3 -> 6683.3333 | E7: 0.25 | F7: 2 | G7: =sumif($C$6:$C45,F7,$D$6:$D45) -> 0 | H7: =H6-I7+G7 -> 1343.75 | I7: =sum(L7:AH7) -> 1253.125 | K7: 2 | L7: =if((L3-L6)>0.1,L6,0) -> 1253.125 | O7: 0 | P7: 0 | S7: 0 | T7: 0 | U7: 0 | V7: 0 | W7: 0 | AA7: =if($K7=$F$4,AA$3,0) -> 0 | AB7: =if($K7=$F$4,AB$3,0) -> 0 | AC7: =if($K7=$F$4,AC$3,0) -> 0 | AD7: =if($K7=$F$4,AD$3,0) -> 0 | AE7: =if($K7=$F$4,AE$3,0) -> 0 | AF7: =if($K7=$F$4,AF$3,0) -> 0 | AG7: =if($K7=$F$4,AG$3,0) -> 0 | AH7: =if($K7=$F$4,AH$3,0) -> 0
B8: Lender Draw 2 at 50% | C8: =F4*E8 -> 8 | D8: ='Aquisitions Deal Analyzer'!$E$12/3 -> 6683.3333 | E8: 0.5 | F8: 3 | G8: =sumif($C$6:$C46,F8,$D$6:$D46) -> 0 | H8: =H7-I8+G8 -> 90.625 | I8: =sum(L8:AH8) -> 1253.125 | K8: 3 | L8: =if((L3-L6-L7)>0.1,L7,0) -> 1253.125 | O8: 0 | P8: 0 | S8: 0 | T8: 0 | U8: 0 | V8: 0 | W8: 0 | AA8: =if($K8=$F$4,AA$3,0) -> 0 | AB8: =if($K8=$F$4,AB$3,0) -> 0 | AC8: =if($K8=$F$4,AC$3,0) -> 0 | AD8: =if($K8=$F$4,AD$3,0) -> 0 | AE8: =if($K8=$F$4,AE$3,0) -> 0 | AF8: =if($K8=$F$4,AF$3,0) -> 0 | AG8: =if($K8=$F$4,AG$3,0) -> 0 | AH8: =if($K8=$F$4,AH$3,0) -> 0
B9: Lender Draw 3 at 75% | C9: =F4*E9 -> 12 | D9: ='Aquisitions Deal Analyzer'!$E$12/3 -> 6683.3333 | E9: 0.75 | F9: 4 | G9: =sumif($C$6:$C47,F9,$D$6:$D47) -> 6683.3333 | H9: =H8-I9+G9 -> 5520.8333 | I9: =sum(L9:AH9) -> 1253.125 | K9: 4 | L9: =if((L3-L6-L7-L8)>0.1,L8,0) -> 1253.125 | O9: 0 | P9: 0 | S9: 0 | T9: 0 | U9: 0 | V9: 0 | W9: 0 | AA9: =if($K9=$F$4,AA$3,0) -> 0 | AB9: =if($K9=$F$4,AB$3,0) -> 0 | AC9: =if($K9=$F$4,AC$3,0) -> 0 | AD9: =if($K9=$F$4,AD$3,0) -> 0 | AE9: =if($K9=$F$4,AE$3,0) -> 0 | AF9: =if($K9=$F$4,AF$3,0) -> 0 | AG9: =if($K9=$F$4,AG$3,0) -> 0 | AH9: =if($K9=$F$4,AH$3,0) -> 0
B10: Property Sale | C10: =F4 -> 16 | D10: ='Aquisitions Deal Analyzer'!E13 -> 300000 | F10: 5 | G10: =sumif($C$6:$C48,F10,$D$6:$D48) -> 0 | H10: =H9-I10+G10 -> 1484.375 | I10: =sum(L10:AH10) -> 4036.4583 | K10: 5 | L10: =if((L3-L6-L7-L8-L9)>0.1,L9,0) -> 1253.125 | O10: =if((O3-O6)>0.1,O6,0) -> 0 | P10: =if((P3-P6)>0.1,P6,0) -> 2333.3333 | S10: =if((S3-S6)>0.1,S6,0) -> 100 | T10: =if((T3-T6)>0.1,T6,0) -> 150 | U10: =if((U3-U6)>0.1,U6,0) -> 100 | V10: =if((V3-V6)>0.1,V6,0) -> 100 | W10: =if((W3-W6)>0.1,W6,0) -> 0 | AA10: =if($K10=$F$4,AA$3,0) -> 0 | AB10: =if($K10=$F$4,AB$3,0) -> 0 | AC10: =if($K10=$F$4,AC$3,0) -> 0 | AD10: =if($K10=$F$4,AD$3,0) -> 0 | AE10: =if($K10=$F$4,AE$3,0) -> 0 | AF10: =if($K10=$F$4,AF$3,0) -> 0 | AG10: =if($K10=$F$4,AG$3,0) -> 0 | AH10: =if($K10=$F$4,AH$3,0) -> 0
B11: Purchase Loan Repayment | C11: =F4 -> 16 | D11: =-'Aquisitions Deal Analyzer'!E11 -> -200000 | F11: 6 | G11: =sumif($C$6:$C49,F11,$D$6:$D49) -> 0 | H11: =H10-I11+G11 -> 231.25 | I11: =sum(L11:AH11) -> 1253.125 | K11: 6 | L11: =if((L3-L6-L7-L8-L9-L10)>0.1,L10,0) -> 1253.125 | O11: 0 | P11: 0 | S11: 0 | T11: 0 | U11: 0 | V11: 0 | W11: 0 | AA11: =if($K11=$F$4,AA$3,0) -> 0 | AB11: =if($K11=$F$4,AB$3,0) -> 0 | AC11: =if($K11=$F$4,AC$3,0) -> 0 | AD11: =if($K11=$F$4,AD$3,0) -> 0 | AE11: =if($K11=$F$4,AE$3,0) -> 0 | AF11: =if($K11=$F$4,AF$3,0) -> 0 | AG11: =if($K11=$F$4,AG$3,0) -> 0 | AH11: =if($K11=$F$4,AH$3,0) -> 0
B12: Construction Loan Repayment | C12: =F4 -> 16 | D12: =-'Aquisitions Deal Analyzer'!E12 -> -20050 | F12: 7 | G12: =sumif($C$6:$C50,F12,$D$6:$D50) -> 0 | H12: =H11-I12+G12 -> -1021.875 | I12: =sum(L12:AH12) -> 1253.125 | K12: 7 | L12: =if((L3-L6-L7-L8-L9-L10-L11)>0.1,L11,0) -> 1253.125 | O12: 0 | P12: 0 | S12: 0 | T12: 0 | U12: 0 | V12: 0 | W12: 0 | AA12: =if($K12=$F$4,AA$3,0) -> 0 | AB12: =if($K12=$F$4,AB$3,0) -> 0 | AC12: =if($K12=$F$4,AC$3,0) -> 0 | AD12: =if($K12=$F$4,AD$3,0) -> 0 | AE12: =if($K12=$F$4,AE$3,0) -> 0 | AF12: =if($K12=$F$4,AF$3,0) -> 0 | AG12: =if($K12=$F$4,AG$3,0) -> 0 | AH12: =if($K12=$F$4,AH$3,0) -> 0
B13: Other Expense 1 | F13: 8 | G13: =sumif($C$6:$C51,F13,$D$6:$D51) -> 6683.3333 | H13: =H12-I13+G13 -> 4408.3333 | I13: =sum(L13:AH13) -> 1253.125 | K13: 8 | L13: =if((L3-L6-L7-L8-L9-L10-L11-L12)>0.1,L12,0) -> 1253.125 | O13: 0 | P13: 0 | S13: 0 | T13: 0 | U13: 0 | V13: 0 | W13: 0 | AA13: =if($K13=$F$4,AA$3,0) -> 0 | AB13: =if($K13=$F$4,AB$3,0) -> 0 | AC13: =if($K13=$F$4,AC$3,0) -> 0 | AD13: =if($K13=$F$4,AD$3,0) -> 0 | AE13: =if($K13=$F$4,AE$3,0) -> 0 | AF13: =if($K13=$F$4,AF$3,0) -> 0 | AG13: =if($K13=$F$4,AG$3,0) -> 0 | AH13: =if($K13=$F$4,AH$3,0) -> 0
B14: Other Expense 2 | F14: 9 | G14: =sumif($C$6:$C52,F14,$D$6:$D52) -> 0 | H14: =H13-I14+G14 -> 371.875 | I14: =sum(L14:AH14) -> 4036.4583 | K14: 9 | L14: =if((L3-L6-L7-L8-L9-L10-L11-L12-L13)>0.1,L13,0) -> 1253.125 | O14: =if((O3-O6-O10)>0.1,O10,0) -> 0 | P14: =if((P3-P6-P10)>0.1,P10,0) -> 2333.3333 | S14: =if((S3-S6-S10)>0.1,S10,0) -> 100 | T14: =if((T3-T6-T10)>0.1,T10,0) -> 150 | U14: =if((U3-U6-U10)>0.1,U10,0) -> 100 | V14: =if((V3-V6-V10)>0.1,V10,0) -> 100 | W14: =if((W3-W6-W10)>0.1,W10,0) -> 0 | AA14: =if($K14=$F$4,AA$3,0) -> 0 | AB14: =if($K14=$F$4,AB$3,0) -> 0 | AC14: =if($K14=$F$4,AC$3,0) -> 0 | AD14: =if($K14=$F$4,AD$3,0) -> 0 | AE14: =if($K14=$F$4,AE$3,0) -> 0 | AF14: =if($K14=$F$4,AF$3,0) -> 0 | AG14: =if($K14=$F$4,AG$3,0) -> 0 | AH14: =if($K14=$F$4,AH$3,0) -> 0
B15: Other Expense 3 | F15: 10 | G15: =sumif($C$6:$C53,F15,$D$6:$D53) -> 0 | H15: =H14-I15+G15 -> -881.25 | I15: =sum(L15:AH15) -> 1253.125 | K15: 10 | L15: =if((L3-L6-L7-L8-L9-L10-L11-L12-L13-L14)>0.1,L14,0) -> 1253.125 | O15: 0 | P15: 0 | S15: 0 | T15: 0 | U15: 0 | V15: 0 | W15: 0 | AA15: =if($K15=$F$4,AA$3,0) -> 0 | AB15: =if($K15=$F$4,AB$3,0) -> 0 | AC15: =if($K15=$F$4,AC$3,0) -> 0 | AD15: =if($K15=$F$4,AD$3,0) -> 0 | AE15: =if($K15=$F$4,AE$3,0) -> 0 | AF15: =if($K15=$F$4,AF$3,0) -> 0 | AG15: =if($K15=$F$4,AG$3,0) -> 0 | AH15: =if($K15=$F$4,AH$3,0) -> 0
B16: Other Expense 4 | F16: 11 | G16: =sumif($C$6:$C54,F16,$D$6:$D54) -> 0 | H16: =H15-I16+G16 -> -2134.375 | I16: =sum(L16:AH16) -> 1253.125 | K16: 11 | L16: =if((L3-L6-L7-L8-L9-L10-L11-L12-L13-L14-15)>0.1,L15,0) -> 1253.125 | O16: 0 | P16: 0 | S16: 0 | T16: 0 | U16: 0 | V16: 0 | W16: 0 | AA16: =if($K16=$F$4,AA$3,0) -> 0 | AB16: =if($K16=$F$4,AB$3,0) -> 0 | AC16: =if($K16=$F$4,AC$3,0) -> 0 | AD16: =if($K16=$F$4,AD$3,0) -> 0 | AE16: =if($K16=$F$4,AE$3,0) -> 0 | AF16: =if($K16=$F$4,AF$3,0) -> 0 | AG16: =if($K16=$F$4,AG$3,0) -> 0 | AH16: =if($K16=$F$4,AH$3,0) -> 0
B17: Other Expense 5 | F17: 12 | G17: =sumif($C$6:$C55,F17,$D$6:$D55) -> 6683.3333 | H17: =H16-I17+G17 -> 3295.8333 | I17: =sum(L17:AH17) -> 1253.125 | K17: 12 | L17: =if((L3-L6-L7-L8-L9-L10-L11-L12-L13-L14-L15-L16)>0.1,L16,0) -> 1253.125 | O17: 0 | P17: 0 | S17: 0 | T17: 0 | U17: 0 | V17: 0 | W17: 0 | AA17: =if($K17=$F$4,AA$3,0) -> 0 | AB17: =if($K17=$F$4,AB$3,0) -> 0 | AC17: =if($K17=$F$4,AC$3,0) -> 0 | AD17: =if($K17=$F$4,AD$3,0) -> 0 | AE17: =if($K17=$F$4,AE$3,0) -> 0 | AF17: =if($K17=$F$4,AF$3,0) -> 0 | AG17: =if($K17=$F$4,AG$3,0) -> 0 | AH17: =if($K17=$F$4,AH$3,0) -> 0
F18: 13 | G18: =sumif($C$6:$C56,F18,$D$6:$D56) -> 0 | H18: =H17-I18+G18 -> -740.625 | I18: =sum(L18:AH18) -> 4036.4583 | K18: 13 | L18: =if((L3-L6-L7-L8-L9-L10-L11-L12-L13-L14-L15-L16-L17)>0.1,L17,0) -> 1253.125 | O18: =if((O3-O6-O10-O14)>0.1,O14,0) -> 0 | P18: =if((P3-P6-P10-P14)>0.1,P14,0) -> 2333.3333 | S18: =if((S3-S6-S10-S14)>0.1,S14,0) -> 100 | T18: =if((T3-T6-T10-T14)>0.1,T14,0) -> 150 | U18: =if((U3-U6-U10-U14)>0.1,U14,0) -> 100 | V18: =if((V3-V6-V10-V14)>0.1,V14,0) -> 100 | W18: =if((W3-W6-W10-W14)>0.1,W14,0) -> 0 | AA18: =if($K18=$F$4,AA$3,0) -> 0 | AB18: =if($K18=$F$4,AB$3,0) -> 0 | AC18: =if($K18=$F$4,AC$3,0) -> 0 | AD18: =if($K18=$F$4,AD$3,0) -> 0 | AE18: =if($K18=$F$4,AE$3,0) -> 0 | AF18: =if($K18=$F$4,AF$3,0) -> 0 | AG18: =if($K18=$F$4,AG$3,0) -> 0 | AH18: =if($K18=$F$4,AH$3,0) -> 0
F19: 14 | G19: =sumif($C$6:$C57,F19,$D$6:$D57) -> 0 | H19: =H18-I19+G19 -> -1993.75 | I19: =sum(L19:AH19) -> 1253.125 | K19: 14 | L19: =if((L3-L6-L7-L8-L9-L10-L11-L12-L13-L14-L15-L16-L17-L18)>0.1,L18,0) -> 1253.125 | O19: 0 | P19: 0 | S19: 0 | T19: 0 | U19: 0 | V19: 0 | W19: 0 | AA19: =if($K19=$F$4,AA$3,0) -> 0 | AB19: =if($K19=$F$4,AB$3,0) -> 0 | AC19: =if($K19=$F$4,AC$3,0) -> 0 | AD19: =if($K19=$F$4,AD$3,0) -> 0 | AE19: =if($K19=$F$4,AE$3,0) -> 0 | AF19: =if($K19=$F$4,AF$3,0) -> 0 | AG19: =if($K19=$F$4,AG$3,0) -> 0 | AH19: =if($K19=$F$4,AH$3,0) -> 0
F20: 15 | G20: =sumif($C$6:$C58,F20,$D$6:$D58) -> 0 | H20: =H19-I20+G20 -> -3246.875 | I20: =sum(L20:AH20) -> 1253.125 | K20: 15 | L20: =if((L3-L6-L7-L8-L9-L10-L11-L12-L13-L14-L15-L16-L17-L18-L19)>0.1,L19,0) -> 1253.125 | O20: 0 | P20: 0 | S20: 0 | T20: 0 | U20: 0 | V20: 0 | W20: 0 | AA20: =if($K20=$F$4,AA$3,0) -> 0 | AB20: =if($K20=$F$4,AB$3,0) -> 0 | AC20: =if($K20=$F$4,AC$3,0) -> 0 | AD20: =if($K20=$F$4,AD$3,0) -> 0 | AE20: =if($K20=$F$4,AE$3,0) -> 0 | AF20: =if($K20=$F$4,AF$3,0) -> 0 | AG20: =if($K20=$F$4,AG$3,0) -> 0 | AH20: =if($K20=$F$4,AH$3,0) -> 0
F21: 16 | G21: =sumif($C$6:$C59,F21,$D$6:$D59) -> 79950 | H21: =H20-I21+G21 -> 67420 | I21: =sum(L21:AH21) -> 9283.125 | K21: 16 | L21: =if((L3-L6-L7-L8-L9-L10-L11-L12-L13-L14-L15-L16-L17-L18-L19-L20)>0.1,L20,0) -> 1253.125 | O21: 0 | P21: 0 | S21: 0 | T21: 0 | U21: 0 | V21: 0 | W21: 0 | AA21: =if($K21=$F$4,AA$3,0) -> 1500 | AB21: =if($K21=$F$4,AB$3,0) -> 500 | AC21: =if($K21=$F$4,AC$3,0) -> 6000 | AD21: =if($K21=$F$4,AD$3,0) -> 30 | AE21: =if($K21=$F$4,AE$3,0) -> 0 | AF21: =if($K21=$F$4,AF$3,0) -> 0 | AG21: =if($K21=$F$4,AG$3,0) -> 0 | AH21: =if($K21=$F$4,AH$3,0) -> 0
F22: 17 | G22: =sumif($C$6:$C60,F22,$D$6:$D60) -> 0 | H22: =H21-I22+G22 -> 67420 | I22: =sum(L22:AH22) -> 0 | K22: 17 | L22: =if((L3-L6-L7-L8-L9-L10-L11-L12-L13-L14-L15-L16-L17-L18-L19-L20-L21)>0.1,L21,0) -> 0 | O22: =if((O3-O6-O10-O14-O18)>0.1,O18,0) -> 0 | P22: =if((P3-P6-P10-P14-P18)>0.1,P18,0) -> 0 | S22: =if((S3-S6-S10-S14-S18)>0.1,S18,0) -> 0 | T22: =if((T3-T6-T10-T14-T18)>0.1,T18,0) -> 0 | U22: =if((U3-U6-U10-U14-U18)>0.1,U18,0) -> 0 | V22: =if((V3-V6-V10-V14-V18)>0.1,V18,0) -> 0 | W22: =if((W3-W6-W10-W14-W18)>0.1,W18,0) -> 0 | AA22: =if($K22=$F$4,AA$3,0) -> 0 | AB22: =if($K22=$F$4,AB$3,0) -> 0 | AC22: =if($K22=$F$4,AC$3,0) -> 0 | AD22: =if($K22=$F$4,AD$3,0) -> 0 | AE22: =if($K22=$F$4,AE$3,0) -> 0 | AF22: =if($K22=$F$4,AF$3,0) -> 0 | AG22: =if($K22=$F$4,AG$3,0) -> 0 | AH22: =if($K22=$F$4,AH$3,0) -> 0
F23: 18 | G23: =sumif($C$6:$C61,F23,$D$6:$D61) -> 0 | H23: =H22-I23+G23 -> 67420 | I23: =sum(L23:AH23) -> 0 | K23: 18 | L23: =if((L3-L6-L7-L8-L9-L10-L11-L12-L13-L14-L15-L16-L17-L18-L19-L20-L21-L22)>0.1,L22,0) -> 0 | O23: 0 | P23: 0 | S23: 0 | T23: 0 | U23: 0 | V23: 0 | W23: 0 | AA23: =if($K23=$F$4,AA$3,0) -> 0 | AB23: =if($K23=$F$4,AB$3,0) -> 0 | AC23: =if($K23=$F$4,AC$3,0) -> 0 | AD23: =if($K23=$F$4,AD$3,0) -> 0 | AE23: =if($K23=$F$4,AE$3,0) -> 0 | AF23: =if($K23=$F$4,AF$3,0) -> 0 | AG23: =if($K23=$F$4,AG$3,0) -> 0 | AH23: =if($K23=$F$4,AH$3,0) -> 0
F24: 19 | G24: =sumif($C$6:$C62,F24,$D$6:$D62) -> 0 | H24: =H23-I24+G24 -> 67420 | I24: =sum(L24:AH24) -> 0 | K24: 19 | L24: =if((L3-L6-L7-L8-L9-L10-L11-L12-L13-L14-L15-L16-L17-L18-L19-L20-L21-L22-L23)>0.1,L23,0) -> 0 | O24: 0 | P24: 0 | S24: 0 | T24: 0 | U24: 0 | V24: 0 | W24: 0 | AA24: =if($K24=$F$4,AA$3,0) -> 0 | AB24: =if($K24=$F$4,AB$3,0) -> 0 | AC24: =if($K24=$F$4,AC$3,0) -> 0 | AD24: =if($K24=$F$4,AD$3,0) -> 0 | AE24: =if($K24=$F$4,AE$3,0) -> 0 | AF24: =if($K24=$F$4,AF$3,0) -> 0 | AG24: =if($K24=$F$4,AG$3,0) -> 0 | AH24: =if($K24=$F$4,AH$3,0) -> 0
F25: 20 | G25: =sumif($C$6:$C63,F25,$D$6:$D63) -> 0 | H25: =H24-I25+G25 -> 67420 | I25: =sum(L25:AH25) -> 0 | K25: 20 | L25: =if((L3-L6-L7-L8-L9-L10-L11-L12-L13-L14-L15-L16-L17-L18-L19-L20-L21-L22-L23-L24)>0.1,L24,0) -> 0 | O25: 0 | P25: 0 | S25: 0 | T25: 0 | U25: 0 | V25: 0 | W25: 0 | AA25: =if($K25=$F$4,AA$3,0) -> 0 | AB25: =if($K25=$F$4,AB$3,0) -> 0 | AC25: =if($K25=$F$4,AC$3,0) -> 0 | AD25: =if($K25=$F$4,AD$3,0) -> 0 | AE25: =if($K25=$F$4,AE$3,0) -> 0 | AF25: =if($K25=$F$4,AF$3,0) -> 0 | AG25: =if($K25=$F$4,AG$3,0) -> 0 | AH25: =if($K25=$F$4,AH$3,0) -> 0
F26: 21 | G26: =sumif($C$6:$C64,F26,$D$6:$D64) -> 0 | H26: =H25-I26+G26 -> 67420 | I26: =sum(L26:AH26) -> 0 | K26: 21 | L26: =if((L3-L6-L7-L8-L9-L10-L11-L12-L13-L14-L15-L16-L17-L18-L19-L20-L21-L22-L23-L24-L25)>0.1,L25,0) -> 0 | O26: =if((O3-O6-O10-O14-O18-O22)>0.1,O22,0) -> 0 | P26: =if((P3-P6-P10-P14-P18-P22)>0.1,P22,0) -> 0 | S26: =if((S3-S6-S10-S14-S18-S22)>0.1,S22,0) -> 0 | T26: =if((T3-T6-T10-T14-T18-T22)>0.1,T22,0) -> 0 | U26: =if((U3-U6-U10-U14-U18-U22)>0.1,U22,0) -> 0 | V26: =if((V3-V6-V10-V14-V18-V22)>0.1,V22,0) -> 0 | W26: =if((W3-W6-W10-W14-W18-W22)>0.1,W22,0) -> 0 | AA26: =if($K26=$F$4,AA$3,0) -> 0 | AB26: =if($K26=$F$4,AB$3,0) -> 0 | AC26: =if($K26=$F$4,AC$3,0) -> 0 | AD26: =if($K26=$F$4,AD$3,0) -> 0 | AE26: =if($K26=$F$4,AE$3,0) -> 0 | AF26: =if($K26=$F$4,AF$3,0) -> 0 | AG26: =if($K26=$F$4,AG$3,0) -> 0 | AH26: =if($K26=$F$4,AH$3,0) -> 0
F27: 22 | G27: =sumif($C$6:$C65,F27,$D$6:$D65) -> 0 | H27: =H26-I27+G27 -> 67420 | I27: =sum(L27:AH27) -> 0 | K27: 22 | L27: =if((L3-L6-L7-L8-L9-L10-L11-L12-L13-L14-L15-L16-L17-L18-L19-L20-L21-L22-L23-L24-L25-L26)>0.1,L26,0) -> 0 | O27: 0 | P27: 0 | S27: 0 | T27: 0 | U27: 0 | V27: 0 | W27: 0 | AA27: =if($K27=$F$4,AA$3,0) -> 0 | AB27: =if($K27=$F$4,AB$3,0) -> 0 | AC27: =if($K27=$F$4,AC$3,0) -> 0 | AD27: =if($K27=$F$4,AD$3,0) -> 0 | AE27: =if($K27=$F$4,AE$3,0) -> 0 | AF27: =if($K27=$F$4,AF$3,0) -> 0 | AG27: =if($K27=$F$4,AG$3,0) -> 0 | AH27: =if($K27=$F$4,AH$3,0) -> 0
F28: 23 | G28: =sumif($C$6:$C66,F28,$D$6:$D66) -> 0 | H28: =H27-I28+G28 -> 67420 | I28: =sum(L28:AH28) -> 0 | K28: 23 | L28: =if((L3-L6-L7-L8-L9-L10-L11-L12-L13-L14-L15-L16-L17-L18-L19-L20-L21-L22-L23-L24-L25-L26-L27)>0.1,L27,0) -> 0 | O28: 0 | P28: 0 | S28: 0 | T28: 0 | U28: 0 | V28: 0 | W28: 0 | AA28: =if($K28=$F$4,AA$3,0) -> 0 | AB28: =if($K28=$F$4,AB$3,0) -> 0 | AC28: =if($K28=$F$4,AC$3,0) -> 0 | AD28: =if($K28=$F$4,AD$3,0) -> 0 | AE28: =if($K28=$F$4,AE$3,0) -> 0 | AF28: =if($K28=$F$4,AF$3,0) -> 0 | AG28: =if($K28=$F$4,AG$3,0) -> 0 | AH28: =if($K28=$F$4,AH$3,0) -> 0
F29: 24 | G29: =sumif($C$6:$C67,F29,$D$6:$D67) -> 0 | H29: =H28-I29+G29 -> 67420 | I29: =sum(L29:AH29) -> 0 | K29: 24 | L29: =if((L3-L6-L7-L8-L9-L10-L11-L12-L13-L14-L15-L16-L17-L18-L19-L20-L21-L22-L23-L24-L25-L26-L27-L28)>0.1,L28,0) -> 0 | O29: 0 | P29: 0 | S29: 0 | T29: 0 | U29: 0 | V29: 0 | W29: 0 | AA29: =if($K29=$F$4,AA$3,0) -> 0 | AB29: =if($K29=$F$4,AB$3,0) -> 0 | AC29: =if($K29=$F$4,AC$3,0) -> 0 | AD29: =if($K29=$F$4,AD$3,0) -> 0 | AE29: =if($K29=$F$4,AE$3,0) -> 0 | AF29: =if($K29=$F$4,AF$3,0) -> 0 | AG29: =if($K29=$F$4,AG$3,0) -> 0 | AH29: =if($K29=$F$4,AH$3,0) -> 0
F30: 25 | G30: =sumif($C$6:$C68,F30,$D$6:$D68) -> 0 | H30: =H29-I30+G30 -> 67420 | I30: =sum(L30:AH30) -> 0 | K30: 25 | L30: =if((L3-L6-L7-L8-L9-L10-L11-L12-L13-L14-L15-L16-L17-L18-L19-L20-L21-L22-L23-L24-L25-L26-L27-L28-L29)>0.1,L29,0) -> 0 | O30: =if((O3-O6-O10-O14-O18-O22-O26)>0.1,O26,0) -> 0 | P30: =if((P3-P6-P10-P14-P18-P22-P26)>0.1,P26,0) -> 0 | S30: =if((S3-S6-S10-S14-S18-S22-S26)>0.1,S26,0) -> 0 | T30: =if((T3-T6-T10-T14-T18-T22-T26)>0.1,T26,0) -> 0 | U30: =if((U3-U6-U10-U14-U18-U22-U26)>0.1,U26,0) -> 0 | V30: =if((V3-V6-V10-V14-V18-V22-V26)>0.1,V26,0) -> 0 | W30: =if((W3-W6-W10-W14-W18-W22-W26)>0.1,W26,0) -> 0 | AA30: =if($K30=$F$4,AA$3,0) -> 0 | AB30: =if($K30=$F$4,AB$3,0) -> 0 | AC30: =if($K30=$F$4,AC$3,0) -> 0 | AD30: =if($K30=$F$4,AD$3,0) -> 0 | AE30: =if($K30=$F$4,AE$3,0) -> 0 | AF30: =if($K30=$F$4,AF$3,0) -> 0 | AG30: =if($K30=$F$4,AG$3,0) -> 0 | AH30: =if($K30=$F$4,AH$3,0) -> 0
F31: 26 | G31: =sumif($C$6:$C69,F31,$D$6:$D69) -> 0 | H31: =H30-I31+G31 -> 67420 | I31: =sum(L31:AH31) -> 0 | K31: 26 | L31: =if((L3-L6-L7-L8-L9-L10-L11-L12-L13-L14-L15-L16-L17-L18-L19-L20-L21-L22-L23-L24-L25-L26-L27-L28-L29-L30)>0.1,L30,0) -> 0 | O31: 0 | P31: 0 | S31: 0 | T31: 0 | U31: 0 | V31: 0 | W31: 0 | AA31: =if($K31=$F$4,AA$3,0) -> 0 | AB31: =if($K31=$F$4,AB$3,0) -> 0 | AC31: =if($K31=$F$4,AC$3,0) -> 0 | AD31: =if($K31=$F$4,AD$3,0) -> 0 | AE31: =if($K31=$F$4,AE$3,0) -> 0 | AF31: =if($K31=$F$4,AF$3,0) -> 0 | AG31: =if($K31=$F$4,AG$3,0) -> 0 | AH31: =if($K31=$F$4,AH$3,0) -> 0
F32: 27 | G32: =sumif($C$6:$C70,F32,$D$6:$D70) -> 0 | H32: =H31-I32+G32 -> 67420 | I32: =sum(L32:AH32) -> 0 | K32: 27 | L32: =if((L3-L6-L7-L8-L9-L10-L11-L12-L13-L14-L15-L16-L17-L18-L19-L20-L21-L22-L23-L24-L25-L26-L27-L28-L29-L30-L31)>0.1,L31,0) -> 0 | O32: 0 | P32: 0 | S32: 0 | T32: 0 | U32: 0 | V32: 0 | W32: 0 | AA32: =if($K32=$F$4,AA$3,0) -> 0 | AB32: =if($K32=$F$4,AB$3,0) -> 0 | AC32: =if($K32=$F$4,AC$3,0) -> 0 | AD32: =if($K32=$F$4,AD$3,0) -> 0 | AE32: =if($K32=$F$4,AE$3,0) -> 0 | AF32: =if($K32=$F$4,AF$3,0) -> 0 | AG32: =if($K32=$F$4,AG$3,0) -> 0 | AH32: =if($K32=$F$4,AH$3,0) -> 0
F33: 28 | G33: =sumif($C$6:$C71,F33,$D$6:$D71) -> 0 | H33: =H32-I33+G33 -> 67420 | I33: =sum(L33:AH33) -> 0 | K33: 28 | L33: =if((L3-L6-L7-L8-L9-L10-L11-L12-L13-L14-L15-L16-L17-L18-L19-L20-L21-L22-L23-L24-L25-L26-L27-L28-L29-L30-L31-L32)>0.1,L32,0) -> 0 | O33: 0 | P33: 0 | S33: 0 | T33: 0 | U33: 0 | V33: 0 | W33: 0 | AA33: =if($K33=$F$4,AA$3,0) -> 0 | AB33: =if($K33=$F$4,AB$3,0) -> 0 | AC33: =if($K33=$F$4,AC$3,0) -> 0 | AD33: =if($K33=$F$4,AD$3,0) -> 0 | AE33: =if($K33=$F$4,AE$3,0) -> 0 | AF33: =if($K33=$F$4,AF$3,0) -> 0 | AG33: =if($K33=$F$4,AG$3,0) -> 0 | AH33: =if($K33=$F$4,AH$3,0) -> 0
F34: 29 | G34: =sumif($C$6:$C72,F34,$D$6:$D72) -> 0 | H34: =H33-I34+G34 -> 67420 | I34: =sum(L34:AH34) -> 0 | K34: 29 | L34: =if((L3-L6-L7-L8-L9-L10-L11-L12-L13-L14-L15-L16-L17-L18-L19-L20-L21-L22-L23-L24-L25-L26-L27-L28-L29-L30-L31-L32-L33)>0.1,L33,0) -> 0 | O34: =if((O3-O6-O10-O14-O18-O22-O26-O30)>0.1,O30,0) -> 0 | P34: =if((P3-P6-P10-P14-P18-P22-P26-P30)>0.1,P30,0) -> 0 | S34: =if((S3-S6-S10-S14-S18-S22-S26-S30)>0.1,S30,0) -> 0 | T34: =if((T3-T6-T10-T14-T18-T22-T26-T30)>0.1,T30,0) -> 0 | U34: =if((U3-U6-U10-U14-U18-U22-U26-U30)>0.1,U30,0) -> 0 | V34: =if((V3-V6-V10-V14-V18-V22-V26-V30)>0.1,V30,0) -> 0 | W34: =if((W3-W6-W10-W14-W18-W22-W26-W30)>0.1,W30,0) -> 0 | AA34: =if($K34=$F$4,AA$3,0) -> 0 | AB34: =if($K34=$F$4,AB$3,0) -> 0 | AC34: =if($K34=$F$4,AC$3,0) -> 0 | AD34: =if($K34=$F$4,AD$3,0) -> 0 | AE34: =if($K34=$F$4,AE$3,0) -> 0 | AF34: =if($K34=$F$4,AF$3,0) -> 0 | AG34: =if($K34=$F$4,AG$3,0) -> 0 | AH34: =if($K34=$F$4,AH$3,0) -> 0
F35: 30 | G35: =sumif($C$6:$C73,F35,$D$6:$D73) -> 0 | H35: =H34-I35+G35 -> 67420 | I35: =sum(L35:AH35) -> 0 | K35: 30 | L35: =if((L3-L6-L7-L8-L9-L10-L11-L12-L13-L14-L15-L16-L17-L18-L19-L20-L21-L22-L23-L24-L25-L26-L27-L28-L29-L30-L31-L32-L33-L34)>0.1,L34,0) -> 0 | O35: 0 | P35: 0 | S35: 0 | T35: 0 | U35: 0 | V35: 0 | W35: 0 | AA35: =if($K35=$F$4,AA$3,0) -> 0 | AB35: =if($K35=$F$4,AB$3,0) -> 0 | AC35: =if($K35=$F$4,AC$3,0) -> 0 | AD35: =if($K35=$F$4,AD$3,0) -> 0 | AE35: =if($K35=$F$4,AE$3,0) -> 0 | AF35: =if($K35=$F$4,AF$3,0) -> 0 | AG35: =if($K35=$F$4,AG$3,0) -> 0 | AH35: =if($K35=$F$4,AH$3,0) -> 0
F36: 31 | G36: =sumif($C$6:$C74,F36,$D$6:$D74) -> 0 | H36: =H35-I36+G36 -> 67420 | I36: =sum(L36:AH36) -> 0 | K36: 31 | L36: =if((L3-L6-L7-L8-L9-L10-L11-L12-L13-L14-L15-L16-L17-L18-L19-L20-L21-L22-L23-L24-L25-L26-L27-L28-L29-L30-L31-L32-L33-L34-L35)>0.1,L35,0) -> 0 | O36: 0 | P36: 0 | S36: 0 | T36: 0 | U36: 0 | V36: 0 | W36: 0 | AA36: =if($K36=$F$4,AA$3,0) -> 0 | AB36: =if($K36=$F$4,AB$3,0) -> 0 | AC36: =if($K36=$F$4,AC$3,0) -> 0 | AD36: =if($K36=$F$4,AD$3,0) -> 0 | AE36: =if($K36=$F$4,AE$3,0) -> 0 | AF36: =if($K36=$F$4,AF$3,0) -> 0 | AG36: =if($K36=$F$4,AG$3,0) -> 0 | AH36: =if($K36=$F$4,AH$3,0) -> 0
F37: 32 | G37: =sumif($C$6:$C75,F37,$D$6:$D75) -> 0 | H37: =H36-I37+G37 -> 67420 | I37: =sum(L37:AH37) -> 0 | K37: 32 | L37: =if((L3-L6-L7-L8-L9-L10-L11-L12-L13-L14-L15-L16-L17-L18-L19-L20-L21-L22-L23-L24-L25-L26-L27-L28-L29-L30-L31-L32-L33-L34-L35-L36)>0.1,L36,0) -> 0 | O37: 0 | P37: 0 | S37: 0 | T37: 0 | U37: 0 | V37: 0 | W37: 0 | AA37: =if($K37=$F$4,AA$3,0) -> 0 | AB37: =if($K37=$F$4,AB$3,0) -> 0 | AC37: =if($K37=$F$4,AC$3,0) -> 0 | AD37: =if($K37=$F$4,AD$3,0) -> 0 | AE37: =if($K37=$F$4,AE$3,0) -> 0 | AF37: =if($K37=$F$4,AF$3,0) -> 0 | AG37: =if($K37=$F$4,AG$3,0) -> 0 | AH37: =if($K37=$F$4,AH$3,0) -> 0
F38: 33 | G38: =sumif($C$6:$C76,F38,$D$6:$D76) -> 0 | H38: =H37-I38+G38 -> 67420 | I38: =sum(L38:AH38) -> 0 | K38: 33 | L38: =if((L3-L6-L7-L8-L9-L10-L11-L12-L13-L14-L15-L16-L17-L18-L19-L20-L21-L22-L23-L24-L25-L26-L27-L28-L29-L30-L31-L32-L33-L34-L35-L36-L37)>0.1,L37,0) -> 0 | O38: =if((O3-O6-O10-O14-O18-O22-O26-O30-O34)>0.1,O34,0) -> 0 | P38: =if((P3-P6-P10-P14-P18-P22-P26-P30-P34)>0.1,P34,0) -> 0 | S38: =if((S3-S6-S10-S14-S18-S22-S26-S30-S34)>0.1,S34,0) -> 0 | T38: =if((T3-T6-T10-T14-T18-T22-T26-T30-T34)>0.1,T34,0) -> 0 | U38: =if((U3-U6-U10-U14-U18-U22-U26-U30-U34)>0.1,U34,0) -> 0 | V38: =if((V3-V6-V10-V14-V18-V22-V26-V30-V34)>0.1,V34,0) -> 0 | W38: =if((W3-W6-W10-W14-W18-W22-W26-W30-W34)>0.1,W34,0) -> 0 | AA38: =if($K38=$F$4,AA$3,0) -> 0 | AB38: =if($K38=$F$4,AB$3,0) -> 0 | AC38: =if($K38=$F$4,AC$3,0) -> 0 | AD38: =if($K38=$F$4,AD$3,0) -> 0 | AE38: =if($K38=$F$4,AE$3,0) -> 0 | AF38: =if($K38=$F$4,AF$3,0) -> 0 | AG38: =if($K38=$F$4,AG$3,0) -> 0 | AH38: =if($K38=$F$4,AH$3,0) -> 0
F39: 34 | G39: =sumif($C$6:$C77,F39,$D$6:$D77) -> 0 | H39: =H38-I39+G39 -> 67420 | I39: =sum(L39:AH39) -> 0 | K39: 34 | L39: =if((L3-L6-L7-L8-L9-L10-L11-L12-L13-L14-L15-L16-L17-L18-L19-L20-L21-L22-L23-L24-L25-L26-L27-L28-L29-L30-L31-L32-L33-L34-L35-L36-L37-L38)>0.1,L38,0) -> 0 | O39: 0 | P39: 0 | S39: 0 | T39: 0 | U39: 0 | V39: 0 | W39: 0 | AA39: =if($K39=$F$4,AA$3,0) -> 0 | AB39: =if($K39=$F$4,AB$3,0) -> 0 | AC39: =if($K39=$F$4,AC$3,0) -> 0 | AD39: =if($K39=$F$4,AD$3,0) -> 0 | AE39: =if($K39=$F$4,AE$3,0) -> 0 | AF39: =if($K39=$F$4,AF$3,0) -> 0 | AG39: =if($K39=$F$4,AG$3,0) -> 0 | AH39: =if($K39=$F$4,AH$3,0) -> 0
F40: 35 | G40: =sumif($C$6:$C78,F40,$D$6:$D78) -> 0 | H40: =H39-I40+G40 -> 67420 | I40: =sum(L40:AH40) -> 0 | K40: 35 | L40: =if((L3-L6-L7-L8-L9-L10-L11-L12-L13-L14-L15-L16-L17-L18-L19-L20-L21-L22-L23-L24-L25-L26-L27-L28-L29-L30-L31-L32-L33-L34-L35-L36-L37-L38-L39)>0.1,L39,0) -> 0 | O40: 0 | P40: 0 | S40: 0 | T40: 0 | U40: 0 | V40: 0 | W40: 0 | AA40: =if($K40=$F$4,AA$3,0) -> 0 | AB40: =if($K40=$F$4,AB$3,0) -> 0 | AC40: =if($K40=$F$4,AC$3,0) -> 0 | AD40: =if($K40=$F$4,AD$3,0) -> 0 | AE40: =if($K40=$F$4,AE$3,0) -> 0 | AF40: =if($K40=$F$4,AF$3,0) -> 0 | AG40: =if($K40=$F$4,AG$3,0) -> 0 | AH40: =if($K40=$F$4,AH$3,0) -> 0
...

Sheet Up Front Draw Cash Flow
A1: UP FRONT DRAW CASH FLOW SCHEDULE | K1: COSTS | L1: Construction Costs | M1: Purchase Price | N1: First Mortgage Points: | O1: First Mortgage Interest: | P1: First Mortgage Monthly Interest Only Payment: | Q1: Property Taxes | R1: HOA & Condo Fees | S1: Insurance Costs | T1: Utilities | X1: Buying Transaction Costs | AA1: Selling Transaction Costs | AF1: Staging Costs | AG1: Marketing Costs | AH1: Miscellaneous Selling Costs
A2: THE NUMBERS IN BLUE ARE AUTOMATICALLY CALCULATED. THE BOXES HIGHLIGHTED IN YELLOW ARE MEANT FOR YOU TO FILL OUT! | T2: Gas | U2: Water | V2: Electricity | W2: Miscellaneous | X2: Escrow / Attorney Fees | Y2: Title Insurance/Search Costs | Z2: Miscellaneous Buying Costs | AA2: Escrow / Attorney Fees | AB2: Selling Recording Fees | AC2: Realtor Fees | AD2: Transfer & Conveyance Fees | AE2: Home Warranty
B3: Net Cash In---> | C3: =sum(D6:D43) -> 300000 | F3: Duration Weeks | G3: Beginning Cash Balance ---> | H3: ='Aquisitions Deal Analyzer'!H39 -> 22966.667 | I3: Net Cash Out Below | K3: Estimated Total Costs | L3: ='Aquisitions Deal Analyzer'!E12 -> 20050 | M3: ='Aquisitions Deal Analyzer'!E11 -> 200000 | N3: ='Aquisitions Deal Analyzer'!F20 -> 6000 | O3: ='Aquisitions Deal Analyzer'!F21 -> 0 | P3: ='Aquisitions Deal Analyzer'!F22 -> 9333.3333 | Q3: ='Aquisitions Deal Analyzer'!K19 -> 5833.3333 | R3: ='Aquisitions Deal Analyzer'!K20 -> 0 | S3: ='Aquisitions Deal Analyzer'!K21 -> 400 | T3: ='Aquisitions Deal Analyzer'!K23 -> 600 | U3: ='Aquisitions Deal Analyzer'!K24 -> 400 | V3: ='Aquisitions Deal Analyzer'!K25 -> 400 | W3: ='Aquisitions Deal Analyzer'!K26 -> 0 | X3: ='Aquisitions Deal Analyzer'!F37 -> 1500 | Y3: ='Aquisitions Deal Analyzer'!F38 -> 3000 | Z3: ='Aquisitions Deal Analyzer'!F39 -> 0 | AA3: ='Aquisitions Deal Analyzer'!F42 -> 1500 | AB3: ='Aquisitions Deal Analyzer'!F43 -> 500 | AC3: ='Aquisitions Deal Analyzer'!F44 -> 6000 | AD3: ='Aquisitions Deal Analyzer'!F45 -> 30 | AE3: ='Aquisitions Deal Analyzer'!F46 -> 0 | AF3: ='Aquisitions Deal Analyzer'!F47 -> 0 | AG3: ='Aquisitions Deal Analyzer'!F48 -> 0 | AH3: ='Aquisitions Deal Analyzer'!F49 -> 0
F4: ='Aquisitions Deal Analyzer'!E9*4 -> 16 | I4: =sum(I6:I41) -> 255546.67 | K4: Frequency | L4: Weekly | M4: One Time | N4: One Time | O4: One Time | P4: Monthly | Q4: One Time | R4: One Time | S4: Monthly | T4: Monthly | U4: Monthly | V4: Monthly | W4: Monthly | X4: One Time | Y4: One Time | Z4: One Time | AA4: One Time | AB4: One Time | AC4: One Time | AD4: One Time | AE4: One Time | AF4: One Time | AG4: One Time | AH4: One Time
B5: Cash In Source | C5: Week | D5: Amount | F5: Week | G5: Cash In to the Project During this Week | H5: Balance @ End of Week | I5: Expenses Required | K5: Week
B6: Lender Purchase Loan | C6: 1 | D6: ='Aquisitions Deal Analyzer'!E11 -> 200000 | F6: 1 | G6: =sumif($C$6:$C44,F6,$D$6:$D44) -> 206683.33 | H6: =H4+H3-I6+G6 -> 9280.2083 | I6: =sum(L6:AH6) -> 220369.79 | K6: 1 | L6: =L3/(F4) -> 1253.125 | M6: =M3 -> 200000 | N6: =N3 -> 6000 | O6: =O3/('Aquisitions Deal Analyzer'!$E$9) -> 0 | P6: =P3/('Aquisitions Deal Analyzer'!$E$9) -> 2333.3333 | Q6: =Q3 -> 5833.3333 | R6: =R3 -> 0 | S6: =S3/('Aquisitions Deal Analyzer'!$E$9) -> 100 | T6: =T3/('Aquisitions Deal Analyzer'!$E$9) -> 150 | U6: =U3/('Aquisitions Deal Analyzer'!$E$9) -> 100 | V6: =V3/('Aquisitions Deal Analyzer'!$E$9) -> 100 | W6: =W3/('Aquisitions Deal Analyzer'!$E$9) -> 0 | X6: =X3 -> 1500 | Y6: =Y3 -> 3000 | Z6: =Z3 -> 0 | AA6: =if($K6=$F$4,AA$3,0) -> 0 | AB6: =if($K6=$F$4,AB$3,0) -> 0 | AC6: =if($K6=$F$4,AC$3,0) -> 0 | AD6: =if($K6=$F$4,AD$3,0) -> 0 | AE6: =if($K6=$F$4,AE$3,0) -> 0 | AF6: =if($K6=$F$4,AF$3,0) -> 0 | AG6: =if($K6=$F$4,AG$3,0) -> 0 | AH6: =if($K6=$F$4,AH$3,0) -> 0
B7: Lender Draw 1 at 1% | C7: =roundup($F$4*E7,0) -> 1 | D7: ='Aquisitions Deal Analyzer'!$E$12/3 -> 6683.3333 | E7: 0.01 | F7: 2 | G7: =sumif($C$6:$C45,F7,$D$6:$D45) -> 0 | H7: =H6-I7+G7 -> 8027.0833 | I7: =sum(L7:AH7) -> 1253.125 | K7: 2 | L7: =if((L3-L6)>0.1,L6,0) -> 1253.125 | O7: 0 | P7: 0 | S7: 0 | T7: 0 | U7: 0 | V7: 0 | W7: 0 | AA7: =if($K7=$F$4,AA$3,0) -> 0 | AB7: =if($K7=$F$4,AB$3,0) -> 0 | AC7: =if($K7=$F$4,AC$3,0) -> 0 | AD7: =if($K7=$F$4,AD$3,0) -> 0 | AE7: =if($K7=$F$4,AE$3,0) -> 0 | AF7: =if($K7=$F$4,AF$3,0) -> 0 | AG7: =if($K7=$F$4,AG$3,0) -> 0 | AH7: =if($K7=$F$4,AH$3,0) -> 0
B8: Lender Draw 2 at 33% | C8: =roundup($F$4*E8,0) -> 6 | D8: ='Aquisitions Deal Analyzer'!$E$12/3 -> 6683.3333 | E8: 0.33 | F8: 3 | G8: =sumif($C$6:$C46,F8,$D$6:$D46) -> 0 | H8: =H7-I8+G8 -> 6773.9583 | I8: =sum(L8:AH8) -> 1253.125 | K8: 3 | L8: =if((L3-L6-L7)>0.1,L7,0) -> 1253.125 | O8: 0 | P8: 0 | S8: 0 | T8: 0 | U8: 0 | V8: 0 | W8: 0 | AA8: =if($K8=$F$4,AA$3,0) -> 0 | AB8: =if($K8=$F$4,AB$3,0) -> 0 | AC8: =if($K8=$F$4,AC$3,0) -> 0 | AD8: =if($K8=$F$4,AD$3,0) -> 0 | AE8: =if($K8=$F$4,AE$3,0) -> 0 | AF8: =if($K8=$F$4,AF$3,0) -> 0 | AG8: =if($K8=$F$4,AG$3,0) -> 0 | AH8: =if($K8=$F$4,AH$3,0) -> 0
B9: Lender Draw 3 at 66% | C9: =roundup($F$4*E9,0) -> 11 | D9: ='Aquisitions Deal Analyzer'!$E$12/3 -> 6683.3333 | E9: 0.66 | F9: 4 | G9: =sumif($C$6:$C47,F9,$D$6:$D47) -> 0 | H9: =H8-I9+G9 -> 5520.8333 | I9: =sum(L9:AH9) -> 1253.125 | K9: 4 | L9: =if((L3-L6-L7-L8)>0.1,L8,0) -> 1253.125 | O9: 0 | P9: 0 | S9: 0 | T9: 0 | U9: 0 | V9: 0 | W9: 0 | AA9: =if($K9=$F$4,AA$3,0) -> 0 | AB9: =if($K9=$F$4,AB$3,0) -> 0 | AC9: =if($K9=$F$4,AC$3,0) -> 0 | AD9: =if($K9=$F$4,AD$3,0) -> 0 | AE9: =if($K9=$F$4,AE$3,0) -> 0 | AF9: =if($K9=$F$4,AF$3,0) -> 0 | AG9: =if($K9=$F$4,AG$3,0) -> 0 | AH9: =if($K9=$F$4,AH$3,0) -> 0
B10: Property Sale | C10: =F4 -> 16 | D10: ='Aquisitions Deal Analyzer'!E13 -> 300000 | F10: 5 | G10: =sumif($C$6:$C48,F10,$D$6:$D48) -> 0 | H10: =H9-I10+G10 -> 1484.375 | I10: =sum(L10:AH10) -> 4036.4583 | K10: 5 | L10: =if((L3-L6-L7-L8-L9)>0.1,L9,0) -> 1253.125 | O10: =if((O3-O6)>0.1,O6,0) -> 0 | P10: =if((P3-P6)>0.1,P6,0) -> 2333.3333 | S10: =if((S3-S6)>0.1,S6,0) -> 100 | T10: =if((T3-T6)>0.1,T6,0) -> 150 | U10: =if((U3-U6)>0.1,U6,0) -> 100 | V10: =if((V3-V6)>0.1,V6,0) -> 100 | W10: =if((W3-W6)>0.1,W6,0) -> 0 | AA10: =if($K10=$F$4,AA$3,0) -> 0 | AB10: =if($K10=$F$4,AB$3,0) -> 0 | AC10: =if($K10=$F$4,AC$3,0) -> 0 | AD10: =if($K10=$F$4,AD$3,0) -> 0 | AE10: =if($K10=$F$4,AE$3,0) -> 0 | AF10: =if($K10=$F$4,AF$3,0) -> 0 | AG10: =if($K10=$F$4,AG$3,0) -> 0 | AH10: =if($K10=$F$4,AH$3,0) -> 0
B11: Purchase Loan Repayment | C11: =F4 -> 16 | D11: =-'Aquisitions Deal Analyzer'!E11 -> -200000 | F11: 6 | G11: =sumif($C$6:$C49,F11,$D$6:$D49) -> 6683.3333 | H11: =H10-I11+G11 -> 6914.5833 | I11: =sum(L11:AH11) -> 1253.125 | K11: 6 | L11: =if((L3-L6-L7-L8-L9-L10)>0.1,L10,0) -> 1253.125 | O11: 0 | P11: 0 | S11: 0 | T11: 0 | U11: 0 | V11: 0 | W11: 0 | AA11: =if($K11=$F$4,AA$3,0) -> 0 | AB11: =if($K11=$F$4,AB$3,0) -> 0 | AC11: =if($K11=$F$4,AC$3,0) -> 0 | AD11: =if($K11=$F$4,AD$3,0) -> 0 | AE11: =if($K11=$F$4,AE$3,0) -> 0 | AF11: =if($K11=$F$4,AF$3,0) -> 0 | AG11: =if($K11=$F$4,AG$3,0) -> 0 | AH11: =if($K11=$F$4,AH$3,0) -> 0
B12: Construction Loan Repayment | C12: =F4 -> 16 | D12: =-'Aquisitions Deal Analyzer'!E12 -> -20050 | F12: 7 | G12: =sumif($C$6:$C50,F12,$D$6:$D50) -> 0 | H12: =H11-I12+G12 -> 5661.4583 | I12: =sum(L12:AH12) -> 1253.125 | K12: 7 | L12: =if((L3-L6-L7-L8-L9-L10-L11)>0.1,L11,0) -> 1253.125 | O12: 0 | P12: 0 | S12: 0 | T12: 0 | U12: 0 | V12: 0 | W12: 0 | AA12: =if($K12=$F$4,AA$3,0) -> 0 | AB12: =if($K12=$F$4,AB$3,0) -> 0 | AC12: =if($K12=$F$4,AC$3,0) -> 0 | AD12: =if($K12=$F$4,AD$3,0) -> 0 | AE12: =if($K12=$F$4,AE$3,0) -> 0 | AF12: =if($K12=$F$4,AF$3,0) -> 0 | AG12: =if($K12=$F$4,AG$3,0) -> 0 | AH12: =if($K12=$F$4,AH$3,0) -> 0
F13: 8 | G13: =sumif($C$6:$C51,F13,$D$6:$D51) -> 0 | H13: =H12-I13+G13 -> 4408.3333 | I13: =sum(L13:AH13) -> 1253.125 | K13: 8 | L13: =if((L3-L6-L7-L8-L9-L10-L11-L12)>0.1,L12,0) -> 1253.125 | O13: 0 | P13: 0 | S13: 0 | T13: 0 | U13: 0 | V13: 0 | W13: 0 | AA13: =if($K13=$F$4,AA$3,0) -> 0 | AB13: =if($K13=$F$4,AB$3,0) -> 0 | AC13: =if($K13=$F$4,AC$3,0) -> 0 | AD13: =if($K13=$F$4,AD$3,0) -> 0 | AE13: =if($K13=$F$4,AE$3,0) -> 0 | AF13: =if($K13=$F$4,AF$3,0) -> 0 | AG13: =if($K13=$F$4,AG$3,0) -> 0 | AH13: =if($K13=$F$4,AH$3,0) -> 0
B14: Other Expense 1 | F14: 9 | G14: =sumif($C$6:$C52,F14,$D$6:$D52) -> 0 | H14: =H13-I14+G14 -> 371.875 | I14: =sum(L14:AH14) -> 4036.4583 | K14: 9 | L14: =if((L3-L6-L7-L8-L9-L10-L11-L12-L13)>0.1,L13,0) -> 1253.125 | O14: =if((O3-O6-O10)>0.1,O10,0) -> 0 | P14: =if((P3-P6-P10)>0.1,P10,0) -> 2333.3333 | S14: =if((S3-S6-S10)>0.1,S10,0) -> 100 | T14: =if((T3-T6-T10)>0.1,T10,0) -> 150 | U14: =if((U3-U6-U10)>0.1,U10,0) -> 100 | V14: =if((V3-V6-V10)>0.1,V10,0) -> 100 | W14: =if((W3-W6-W10)>0.1,W10,0) -> 0 | AA14: =if($K14=$F$4,AA$3,0) -> 0 | AB14: =if($K14=$F$4,AB$3,0) -> 0 | AC14: =if($K14=$F$4,AC$3,0) -> 0 | AD14: =if($K14=$F$4,AD$3,0) -> 0 | AE14: =if($K14=$F$4,AE$3,0) -> 0 | AF14: =if($K14=$F$4,AF$3,0) -> 0 | AG14: =if($K14=$F$4,AG$3,0) -> 0 | AH14: =if($K14=$F$4,AH$3,0) -> 0
B15: Other Expense 2 | F15: 10 | G15: =sumif($C$6:$C53,F15,$D$6:$D53) -> 0 | H15: =H14-I15+G15 -> -881.25 | I15: =sum(L15:AH15) -> 1253.125 | K15: 10 | L15: =if((L3-L6-L7-L8-L9-L10-L11-L12-L13-L14)>0.1,L14,0) -> 1253.125 | O15: 0 | P15: 0 | S15: 0 | T15: 0 | U15: 0 | V15: 0 | W15: 0 | AA15: =if($K15=$F$4,AA$3,0) -> 0 | AB15: =if($K15=$F$4,AB$3,0) -> 0 | AC15: =if($K15=$F$4,AC$3,0) -> 0 | AD15: =if($K15=$F$4,AD$3,0) -> 0 | AE15: =if($K15=$F$4,AE$3,0) -> 0 | AF15: =if($K15=$F$4,AF$3,0) -> 0 | AG15: =if($K15=$F$4,AG$3,0) -> 0 | AH15: =if($K15=$F$4,AH$3,0) -> 0
B16: Other Expense 3 | F16: 11 | G16: =sumif($C$6:$C54,F16,$D$6:$D54) -> 6683.3333 | H16: =H15-I16+G16 -> 4548.9583 | I16: =sum(L16:AH16) -> 1253.125 | K16: 11 | L16: =if((L3-L6-L7-L8-L9-L10-L11-L12-L13-L14-15)>0.1,L15,0) -> 1253.125 | O16: 0 | P16: 0 | S16: 0 | T16: 0 | U16: 0 | V16: 0 | W16: 0 | AA16: =if($K16=$F$4,AA$3,0) -> 0 | AB16: =if($K16=$F$4,AB$3,0) -> 0 | AC16: =if($K16=$F$4,AC$3,0) -> 0 | AD16: =if($K16=$F$4,AD$3,0) -> 0 | AE16: =if($K16=$F$4,AE$3,0) -> 0 | AF16: =if($K16=$F$4,AF$3,0) -> 0 | AG16: =if($K16=$F$4,AG$3,0) -> 0 | AH16: =if($K16=$F$4,AH$3,0) -> 0
B17: Other Expense 4 | F17: 12 | G17: =sumif($C$6:$C55,F17,$D$6:$D55) -> 0 | H17: =H16-I17+G17 -> 3295.8333 | I17: =sum(L17:AH17) -> 1253.125 | K17: 12 | L17: =if((L3-L6-L7-L8-L9-L10-L11-L12-L13-L14-L15-L16)>0.1,L16,0) -> 1253.125 | O17: 0 | P17: 0 | S17: 0 | T17: 0 | U17: 0 | V17: 0 | W17: 0 | AA17: =if($K17=$F$4,AA$3,0) -> 0 | AB17: =if($K17=$F$4,AB$3,0) -> 0 | AC17: =if($K17=$F$4,AC$3,0) -> 0 | AD17: =if($K17=$F$4,AD$3,0) -> 0 | AE17: =if($K17=$F$4,AE$3,0) -> 0 | AF17: =if($K17=$F$4,AF$3,0) -> 0 | AG17: =if($K17=$F$4,AG$3,0) -> 0 | AH17: =if($K17=$F$4,AH$3,0) -> 0
B18: Other Expense 5 | F18: 13 | G18: =sumif($C$6:$C56,F18,$D$6:$D56) -> 0 | H18: =H17-I18+G18 -> -740.625 | I18: =sum(L18:AH18) -> 4036.4583 | K18: 13 | L18: =if((L3-L6-L7-L8-L9-L10-L11-L12-L13-L14-L15-L16-L17)>0.1,L17,0) -> 1253.125 | O18: =if((O3-O6-O10-O14)>0.1,O14,0) -> 0 | P18: =if((P3-P6-P10-P14)>0.1,P14,0) -> 2333.3333 | S18: =if((S3-S6-S10-S14)>0.1,S14,0) -> 100 | T18: =if((T3-T6-T10-T14)>0.1,T14,0) -> 150 | U18: =if((U3-U6-U10-U14)>0.1,U14,0) -> 100 | V18: =if((V3-V6-V10-V14)>0.1,V14,0) -> 100 | W18: =if((W3-W6-W10-W14)>0.1,W14,0) -> 0 | AA18: =if($K18=$F$4,AA$3,0) -> 0 | AB18: =if($K18=$F$4,AB$3,0) -> 0 | AC18: =if($K18=$F$4,AC$3,0) -> 0 | AD18: =if($K18=$F$4,AD$3,0) -> 0 | AE18: =if($K18=$F$4,AE$3,0) -> 0 | AF18: =if($K18=$F$4,AF$3,0) -> 0 | AG18: =if($K18=$F$4,AG$3,0) -> 0 | AH18: =if($K18=$F$4,AH$3,0) -> 0
F19: 14 | G19: =sumif($C$6:$C57,F19,$D$6:$D57) -> 0 | H19: =H18-I19+G19 -> -1993.75 | I19: =sum(L19:AH19) -> 1253.125 | K19: 14 | L19: =if((L3-L6-L7-L8-L9-L10-L11-L12-L13-L14-L15-L16-L17-L18)>0.1,L18,0) -> 1253.125 | O19: 0 | P19: 0 | S19: 0 | T19: 0 | U19: 0 | V19: 0 | W19: 0 | AA19: =if($K19=$F$4,AA$3,0) -> 0 | AB19: =if($K19=$F$4,AB$3,0) -> 0 | AC19: =if($K19=$F$4,AC$3,0) -> 0 | AD19: =if($K19=$F$4,AD$3,0) -> 0 | AE19: =if($K19=$F$4,AE$3,0) -> 0 | AF19: =if($K19=$F$4,AF$3,0) -> 0 | AG19: =if($K19=$F$4,AG$3,0) -> 0 | AH19: =if($K19=$F$4,AH$3,0) -> 0
F20: 15 | G20: =sumif($C$6:$C58,F20,$D$6:$D58) -> 0 | H20: =H19-I20+G20 -> -3246.875 | I20: =sum(L20:AH20) -> 1253.125 | K20: 15 | L20: =if((L3-L6-L7-L8-L9-L10-L11-L12-L13-L14-L15-L16-L17-L18-L19)>0.1,L19,0) -> 1253.125 | O20: 0 | P20: 0 | S20: 0 | T20: 0 | U20: 0 | V20: 0 | W20: 0 | AA20: =if($K20=$F$4,AA$3,0) -> 0 | AB20: =if($K20=$F$4,AB$3,0) -> 0 | AC20: =if($K20=$F$4,AC$3,0) -> 0 | AD20: =if($K20=$F$4,AD$3,0) -> 0 | AE20: =if($K20=$F$4,AE$3,0) -> 0 | AF20: =if($K20=$F$4,AF$3,0) -> 0 | AG20: =if($K20=$F$4,AG$3,0) -> 0 | AH20: =if($K20=$F$4,AH$3,0) -> 0
F21: 16 | G21: =sumif($C$6:$C59,F21,$D$6:$D59) -> 79950 | H21: =H20-I21+G21 -> 67420 | I21: =sum(L21:AH21) -> 9283.125 | K21: 16 | L21: =if((L3-L6-L7-L8-L9-L10-L11-L12-L13-L14-L15-L16-L17-L18-L19-L20)>0.1,L20,0) -> 1253.125 | O21: 0 | P21: 0 | S21: 0 | T21: 0 | U21: 0 | V21: 0 | W21: 0 | AA21: =if($K21=$F$4,AA$3,0) -> 1500 | AB21: =if($K21=$F$4,AB$3,0) -> 500 | AC21: =if($K21=$F$4,AC$3,0) -> 6000 | AD21: =if($K21=$F$4,AD$3,0) -> 30 | AE21: =if($K21=$F$4,AE$3,0) -> 0 | AF21: =if($K21=$F$4,AF$3,0) -> 0 | AG21: =if($K21=$F$4,AG$3,0) -> 0 | AH21: =if($K21=$F$4,AH$3,0) -> 0
F22: 17 | G22: =sumif($C$6:$C60,F22,$D$6:$D60) -> 0 | H22: =H21-I22+G22 -> 67420 | I22: =sum(L22:AH22) -> 0 | K22: 17 | L22: =if((L3-L6-L7-L8-L9-L10-L11-L12-L13-L14-L15-L16-L17-L18-L19-L20-L21)>0.1,L21,0) -> 0 | O22: =if((O3-O6-O10-O14-O18)>0.1,O18,0) -> 0 | P22: =if((P3-P6-P10-P14-P18)>0.1,P18,0) -> 0 | S22: =if((S3-S6-S10-S14-S18)>0.1,S18,0) -> 0 | T22: =if((T3-T6-T10-T14-T18)>0.1,T18,0) -> 0 | U22: =if((U3-U6-U10-U14-U18)>0.1,U18,0) -> 0 | V22: =if((V3-V6-V10-V14-V18)>0.1,V18,0) -> 0 | W22: =if((W3-W6-W10-W14-W18)>0.1,W18,0) -> 0 | AA22: =if($K22=$F$4,AA$3,0) -> 0 | AB22: =if($K22=$F$4,AB$3,0) -> 0 | AC22: =if($K22=$F$4,AC$3,0) -> 0 | AD22: =if($K22=$F$4,AD$3,0) -> 0 | AE22: =if($K22=$F$4,AE$3,0) -> 0 | AF22: =if($K22=$F$4,AF$3,0) -> 0 | AG22: =if($K22=$F$4,AG$3,0) -> 0 | AH22: =if($K22=$F$4,AH$3,0) -> 0
F23: 18 | G23: =sumif($C$6:$C61,F23,$D$6:$D61) -> 0 | H23: =H22-I23+G23 -> 67420 | I23: =sum(L23:AH23) -> 0 | K23: 18 | L23: =if((L3-L6-L7-L8-L9-L10-L11-L12-L13-L14-L15-L16-L17-L18-L19-L20-L21-L22)>0.1,L22,0) -> 0 | O23: 0 | P23: 0 | S23: 0 | T23: 0 | U23: 0 | V23: 0 | W23: 0 | AA23: =if($K23=$F$4,AA$3,0) -> 0 | AB23: =if($K23=$F$4,AB$3,0) -> 0 | AC23: =if($K23=$F$4,AC$3,0) -> 0 | AD23: =if($K23=$F$4,AD$3,0) -> 0 | AE23: =if($K23=$F$4,AE$3,0) -> 0 | AF23: =if($K23=$F$4,AF$3,0) -> 0 | AG23: =if($K23=$F$4,AG$3,0) -> 0 | AH23: =if($K23=$F$4,AH$3,0) -> 0
F24: 19 | G24: =sumif($C$6:$C62,F24,$D$6:$D62) -> 0 | H24: =H23-I24+G24 -> 67420 | I24: =sum(L24:AH24) -> 0 | K24: 19 | L24: =if((L3-L6-L7-L8-L9-L10-L11-L12-L13-L14-L15-L16-L17-L18-L19-L20-L21-L22-L23)>0.1,L23,0) -> 0 | O24: 0 | P24: 0 | S24: 0 | T24: 0 | U24: 0 | V24: 0 | W24: 0 | AA24: =if($K24=$F$4,AA$3,0) -> 0 | AB24: =if($K24=$F$4,AB$3,0) -> 0 | AC24: =if($K24=$F$4,AC$3,0) -> 0 | AD24: =if($K24=$F$4,AD$3,0) -> 0 | AE24: =if($K24=$F$4,AE$3,0) -> 0 | AF24: =if($K24=$F$4,AF$3,0) -> 0 | AG24: =if($K24=$F$4,AG$3,0) -> 0 | AH24: =if($K24=$F$4,AH$3,0) -> 0
F25: 20 | G25: =sumif($C$6:$C63,F25,$D$6:$D63) -> 0 | H25: =H24-I25+G25 -> 67420 | I25: =sum(L25:AH25) -> 0 | K25: 20 | L25: =if((L3-L6-L7-L8-L9-L10-L11-L12-L13-L14-L15-L16-L17-L18-L19-L20-L21-L22-L23-L24)>0.1,L24,0) -> 0 | O25: 0 | P25: 0 | S25: 0 | T25: 0 | U25: 0 | V25: 0 | W25: 0 | AA25: =if($K25=$F$4,AA$3,0) -> 0 | AB25: =if($K25=$F$4,AB$3,0) -> 0 | AC25: =if($K25=$F$4,AC$3,0) -> 0 | AD25: =if($K25=$F$4,AD$3,0) -> 0 | AE25: =if($K25=$F$4,AE$3,0) -> 0 | AF25: =if($K25=$F$4,AF$3,0) -> 0 | AG25: =if($K25=$F$4,AG$3,0) -> 0 | AH25: =if($K25=$F$4,AH$3,0) -> 0
F26: 21 | G26: =sumif($C$6:$C64,F26,$D$6:$D64) -> 0 | H26: =H25-I26+G26 -> 67420 | I26: =sum(L26:AH26) -> 0 | K26: 21 | L26: =if((L3-L6-L7-L8-L9-L10-L11-L12-L13-L14-L15-L16-L17-L18-L19-L20-L21-L22-L23-L24-L25)>0.1,L25,0) -> 0 | O26: =if((O3-O6-O10-O14-O18-O22)>0.1,O22,0) -> 0 | P26: =if((P3-P6-P10-P14-P18-P22)>0.1,P22,0) -> 0 | S26: =if((S3-S6-S10-S14-S18-S22)>0.1,S22,0) -> 0 | T26: =if((T3-T6-T10-T14-T18-T22)>0.1,T22,0) -> 0 | U26: =if((U3-U6-U10-U14-U18-U22)>0.1,U22,0) -> 0 | V26: =if((V3-V6-V10-V14-V18-V22)>0.1,V22,0) -> 0 | W26: =if((W3-W6-W10-W14-W18-W22)>0.1,W22,0) -> 0 | AA26: =if($K26=$F$4,AA$3,0) -> 0 | AB26: =if($K26=$F$4,AB$3,0) -> 0 | AC26: =if($K26=$F$4,AC$3,0) -> 0 | AD26: =if($K26=$F$4,AD$3,0) -> 0 | AE26: =if($K26=$F$4,AE$3,0) -> 0 | AF26: =if($K26=$F$4,AF$3,0) -> 0 | AG26: =if($K26=$F$4,AG$3,0) -> 0 | AH26: =if($K26=$F$4,AH$3,0) -> 0
F27: 22 | G27: =sumif($C$6:$C65,F27,$D$6:$D65) -> 0 | H27: =H26-I27+G27 -> 67420 | I27: =sum(L27:AH27) -> 0 | K27: 22 | L27: =if((L3-L6-L7-L8-L9-L10-L11-L12-L13-L14-L15-L16-L17-L18-L19-L20-L21-L22-L23-L24-L25-L26)>0.1,L26,0) -> 0 | O27: 0 | P27: 0 | S27: 0 | T27: 0 | U27: 0 | V27: 0 | W27: 0 | AA27: =if($K27=$F$4,AA$3,0) -> 0 | AB27: =if($K27=$F$4,AB$3,0) -> 0 | AC27: =if($K27=$F$4,AC$3,0) -> 0 | AD27: =if($K27=$F$4,AD$3,0) -> 0 | AE27: =if($K27=$F$4,AE$3,0) -> 0 | AF27: =if($K27=$F$4,AF$3,0) -> 0 | AG27: =if($K27=$F$4,AG$3,0) -> 0 | AH27: =if($K27=$F$4,AH$3,0) -> 0
F28: 23 | G28: =sumif($C$6:$C66,F28,$D$6:$D66) -> 0 | H28: =H27-I28+G28 -> 67420 | I28: =sum(L28:AH28) -> 0 | K28: 23 | L28: =if((L3-L6-L7-L8-L9-L10-L11-L12-L13-L14-L15-L16-L17-L18-L19-L20-L21-L22-L23-L24-L25-L26-L27)>0.1,L27,0) -> 0 | O28: 0 | P28: 0 | S28: 0 | T28: 0 | U28: 0 | V28: 0 | W28: 0 | AA28: =if($K28=$F$4,AA$3,0) -> 0 | AB28: =if($K28=$F$4,AB$3,0) -> 0 | AC28: =if($K28=$F$4,AC$3,0) -> 0 | AD28: =if($K28=$F$4,AD$3,0) -> 0 | AE28: =if($K28=$F$4,AE$3,0) -> 0 | AF28: =if($K28=$F$4,AF$3,0) -> 0 | AG28: =if($K28=$F$4,AG$3,0) -> 0 | AH28: =if($K28=$F$4,AH$3,0) -> 0
F29: 24 | G29: =sumif($C$6:$C67,F29,$D$6:$D67) -> 0 | H29: =H28-I29+G29 -> 67420 | I29: =sum(L29:AH29) -> 0 | K29: 24 | L29: =if((L3-L6-L7-L8-L9-L10-L11-L12-L13-L14-L15-L16-L17-L18-L19-L20-L21-L22-L23-L24-L25-L26-L27-L28)>0.1,L28,0) -> 0 | O29: 0 | P29: 0 | S29: 0 | T29: 0 | U29: 0 | V29: 0 | W29: 0 | AA29: =if($K29=$F$4,AA$3,0) -> 0 | AB29: =if($K29=$F$4,AB$3,0) -> 0 | AC29: =if($K29=$F$4,AC$3,0) -> 0 | AD29: =if($K29=$F$4,AD$3,0) -> 0 | AE29: =if($K29=$F$4,AE$3,0) -> 0 | AF29: =if($K29=$F$4,AF$3,0) -> 0 | AG29: =if($K29=$F$4,AG$3,0) -> 0 | AH29: =if($K29=$F$4,AH$3,0) -> 0
F30: 25 | G30: =sumif($C$6:$C68,F30,$D$6:$D68) -> 0 | H30: =H29-I30+G30 -> 67420 | I30: =sum(L30:AH30) -> 0 | K30: 25 | L30: =if((L3-L6-L7-L8-L9-L10-L11-L12-L13-L14-L15-L16-L17-L18-L19-L20-L21-L22-L23-L24-L25-L26-L27-L28-L29)>0.1,L29,0) -> 0 | O30: =if((O3-O6-O10-O14-O18-O22-O26)>0.1,O26,0) -> 0 | P30: =if((P3-P6-P10-P14-P18-P22-P26)>0.1,P26,0) -> 0 | S30: =if((S3-S6-S10-S14-S18-S22-S26)>0.1,S26,0) -> 0 | T30: =if((T3-T6-T10-T14-T18-T22-T26)>0.1,T26,0) -> 0 | U30: =if((U3-U6-U10-U14-U18-U22-U26)>0.1,U26,0) -> 0 | V30: =if((V3-V6-V10-V14-V18-V22-V26)>0.1,V26,0) -> 0 | W30: =if((W3-W6-W10-W14-W18-W22-W26)>0.1,W26,0) -> 0 | AA30: =if($K30=$F$4,AA$3,0) -> 0 | AB30: =if($K30=$F$4,AB$3,0) -> 0 | AC30: =if($K30=$F$4,AC$3,0) -> 0 | AD30: =if($K30=$F$4,AD$3,0) -> 0 | AE30: =if($K30=$F$4,AE$3,0) -> 0 | AF30: =if($K30=$F$4,AF$3,0) -> 0 | AG30: =if($K30=$F$4,AG$3,0) -> 0 | AH30: =if($K30=$F$4,AH$3,0) -> 0
F31: 26 | G31: =sumif($C$6:$C69,F31,$D$6:$D69) -> 0 | H31: =H30-I31+G31 -> 67420 | I31: =sum(L31:AH31) -> 0 | K31: 26 | L31: =if((L3-L6-L7-L8-L9-L10-L11-L12-L13-L14-L15-L16-L17-L18-L19-L20-L21-L22-L23-L24-L25-L26-L27-L28-L29-L30)>0.1,L30,0) -> 0 | O31: 0 | P31: 0 | S31: 0 | T31: 0 | U31: 0 | V31: 0 | W31: 0 | AA31: =if($K31=$F$4,AA$3,0) -> 0 | AB31: =if($K31=$F$4,AB$3,0) -> 0 | AC31: =if($K31=$F$4,AC$3,0) -> 0 | AD31: =if($K31=$F$4,AD$3,0) -> 0 | AE31: =if($K31=$F$4,AE$3,0) -> 0 | AF31: =if($K31=$F$4,AF$3,0) -> 0 | AG31: =if($K31=$F$4,AG$3,0) -> 0 | AH31: =if($K31=$F$4,AH$3,0) -> 0
F32: 27 | G32: =sumif($C$6:$C70,F32,$D$6:$D70) -> 0 | H32: =H31-I32+G32 -> 67420 | I32: =sum(L32:AH32) -> 0 | K32: 27 | L32: =if((L3-L6-L7-L8-L9-L10-L11-L12-L13-L14-L15-L16-L17-L18-L19-L20-L21-L22-L23-L24-L25-L26-L27-L28-L29-L30-L31)>0.1,L31,0) -> 0 | O32: 0 | P32: 0 | S32: 0 | T32: 0 | U32: 0 | V32: 0 | W32: 0 | AA32: =if($K32=$F$4,AA$3,0) -> 0 | AB32: =if($K32=$F$4,AB$3,0) -> 0 | AC32: =if($K32=$F$4,AC$3,0) -> 0 | AD32: =if($K32=$F$4,AD$3,0) -> 0 | AE32: =if($K32=$F$4,AE$3,0) -> 0 | AF32: =if($K32=$F$4,AF$3,0) -> 0 | AG32: =if($K32=$F$4,AG$3,0) -> 0 | AH32: =if($K32=$F$4,AH$3,0) -> 0
F33: 28 | G33: =sumif($C$6:$C71,F33,$D$6:$D71) -> 0 | H33: =H32-I33+G33 -> 67420 | I33: =sum(L33:AH33) -> 0 | K33: 28 | L33: =if((L3-L6-L7-L8-L9-L10-L11-L12-L13-L14-L15-L16-L17-L18-L19-L20-L21-L22-L23-L24-L25-L26-L27-L28-L29-L30-L31-L32)>0.1,L32,0) -> 0 | O33: 0 | P33: 0 | S33: 0 | T33: 0 | U33: 0 | V33: 0 | W33: 0 | AA33: =if($K33=$F$4,AA$3,0) -> 0 | AB33: =if($K33=$F$4,AB$3,0) -> 0 | AC33: =if($K33=$F$4,AC$3,0) -> 0 | AD33: =if($K33=$F$4,AD$3,0) -> 0 | AE33: =if($K33=$F$4,AE$3,0) -> 0 | AF33: =if($K33=$F$4,AF$3,0) -> 0 | AG33: =if($K33=$F$4,AG$3,0) -> 0 | AH33: =if($K33=$F$4,AH$3,0) -> 0
F34: 29 | G34: =sumif($C$6:$C72,F34,$D$6:$D72) -> 0 | H34: =H33-I34+G34 -> 67420 | I34: =sum(L34:AH34) -> 0 | K34: 29 | L34: =if((L3-L6-L7-L8-L9-L10-L11-L12-L13-L14-L15-L16-L17-L18-L19-L20-L21-L22-L23-L24-L25-L26-L27-L28-L29-L30-L31-L32-L33)>0.1,L33,0) -> 0 | O34: =if((O3-O6-O10-O14-O18-O22-O26-O30)>0.1,O30,0) -> 0 | P34: =if((P3-P6-P10-P14-P18-P22-P26-P30)>0.1,P30,0) -> 0 | S34: =if((S3-S6-S10-S14-S18-S22-S26-S30)>0.1,S30,0) -> 0 | T34: =if((T3-T6-T10-T14-T18-T22-T26-T30)>0.1,T30,0) -> 0 | U34: =if((U3-U6-U10-U14-U18-U22-U26-U30)>0.1,U30,0) -> 0 | V34: =if((V3-V6-V10-V14-V18-V22-V26-V30)>0.1,V30,0) -> 0 | W34: =if((W3-W6-W10-W14-W18-W22-W26-W30)>0.1,W30,0) -> 0 | AA34: =if($K34=$F$4,AA$3,0) -> 0 | AB34: =if($K34=$F$4,AB$3,0) -> 0 | AC34: =if($K34=$F$4,AC$3,0) -> 0 | AD34: =if($K34=$F$4,AD$3,0) -> 0 | AE34: =if($K34=$F$4,AE$3,0) -> 0 | AF34: =if($K34=$F$4,AF$3,0) -> 0 | AG34: =if($K34=$F$4,AG$3,0) -> 0 | AH34: =if($K34=$F$4,AH$3,0) -> 0
F35: 30 | G35: =sumif($C$6:$C73,F35,$D$6:$D73) -> 0 | H35: =H34-I35+G35 -> 67420 | I35: =sum(L35:AH35) -> 0 | K35: 30 | L35: =if((L3-L6-L7-L8-L9-L10-L11-L12-L13-L14-L15-L16-L17-L18-L19-L20-L21-L22-L23-L24-L25-L26-L27-L28-L29-L30-L31-L32-L33-L34)>0.1,L34,0) -> 0 | O35: 0 | P35: 0 | S35: 0 | T35: 0 | U35: 0 | V35: 0 | W35: 0 | AA35: =if($K35=$F$4,AA$3,0) -> 0 | AB35: =if($K35=$F$4,AB$3,0) -> 0 | AC35: =if($K35=$F$4,AC$3,0) -> 0 | AD35: =if($K35=$F$4,AD$3,0) -> 0 | AE35: =if($K35=$F$4,AE$3,0) -> 0 | AF35: =if($K35=$F$4,AF$3,0) -> 0 | AG35: =if($K35=$F$4,AG$3,0) -> 0 | AH35: =if($K35=$F$4,AH$3,0) -> 0
F36: 31 | G36: =sumif($C$6:$C74,F36,$D$6:$D74) -> 0 | H36: =H35-I36+G36 -> 67420 | I36: =sum(L36:AH36) -> 0 | K36: 31 | L36: =if((L3-L6-L7-L8-L9-L10-L11-L12-L13-L14-L15-L16-L17-L18-L19-L20-L21-L22-L23-L24-L25-L26-L27-L28-L29-L30-L31-L32-L33-L34-L35)>0.1,L35,0) -> 0 | O36: 0 | P36: 0 | S36: 0 | T36: 0 | U36: 0 | V36: 0 | W36: 0 | AA36: =if($K36=$F$4,AA$3,0) -> 0 | AB36: =if($K36=$F$4,AB$3,0) -> 0 | AC36: =if($K36=$F$4,AC$3,0) -> 0 | AD36: =if($K36=$F$4,AD$3,0) -> 0 | AE36: =if($K36=$F$4,AE$3,0) -> 0 | AF36: =if($K36=$F$4,AF$3,0) -> 0 | AG36: =if($K36=$F$4,AG$3,0) -> 0 | AH36: =if($K36=$F$4,AH$3,0) -> 0
F37: 32 | G37: =sumif($C$6:$C75,F37,$D$6:$D75) -> 0 | H37: =H36-I37+G37 -> 67420 | I37: =sum(L37:AH37) -> 0 | K37: 32 | L37: =if((L3-L6-L7-L8-L9-L10-L11-L12-L13-L14-L15-L16-L17-L18-L19-L20-L21-L22-L23-L24-L25-L26-L27-L28-L29-L30-L31-L32-L33-L34-L35-L36)>0.1,L36,0) -> 0 | O37: 0 | P37: 0 | S37: 0 | T37: 0 | U37: 0 | V37: 0 | W37: 0 | AA37: =if($K37=$F$4,AA$3,0) -> 0 | AB37: =if($K37=$F$4,AB$3,0) -> 0 | AC37: =if($K37=$F$4,AC$3,0) -> 0 | AD37: =if($K37=$F$4,AD$3,0) -> 0 | AE37: =if($K37=$F$4,AE$3,0) -> 0 | AF37: =if($K37=$F$4,AF$3,0) -> 0 | AG37: =if($K37=$F$4,AG$3,0) -> 0 | AH37: =if($K37=$F$4,AH$3,0) -> 0
F38: 33 | G38: =sumif($C$6:$C76,F38,$D$6:$D76) -> 0 | H38: =H37-I38+G38 -> 67420 | I38: =sum(L38:AH38) -> 0 | K38: 33 | L38: =if((L3-L6-L7-L8-L9-L10-L11-L12-L13-L14-L15-L16-L17-L18-L19-L20-L21-L22-L23-L24-L25-L26-L27-L28-L29-L30-L31-L32-L33-L34-L35-L36-L37)>0.1,L37,0) -> 0 | O38: =if((O3-O6-O10-O14-O18-O22-O26-O30-O34)>0.1,O34,0) -> 0 | P38: =if((P3-P6-P10-P14-P18-P22-P26-P30-P34)>0.1,P34,0) -> 0 | S38: =if((S3-S6-S10-S14-S18-S22-S26-S30-S34)>0.1,S34,0) -> 0 | T38: =if((T3-T6-T10-T14-T18-T22-T26-T30-T34)>0.1,T34,0) -> 0 | U38: =if((U3-U6-U10-U14-U18-U22-U26-U30-U34)>0.1,U34,0) -> 0 | V38: =if((V3-V6-V10-V14-V18-V22-V26-V30-V34)>0.1,V34,0) -> 0 | W38: =if((W3-W6-W10-W14-W18-W22-W26-W30-W34)>0.1,W34,0) -> 0 | AA38: =if($K38=$F$4,AA$3,0) -> 0 | AB38: =if($K38=$F$4,AB$3,0) -> 0 | AC38: =if($K38=$F$4,AC$3,0) -> 0 | AD38: =if($K38=$F$4,AD$3,0) -> 0 | AE38: =if($K38=$F$4,AE$3,0) -> 0 | AF38: =if($K38=$F$4,AF$3,0) -> 0 | AG38: =if($K38=$F$4,AG$3,0) -> 0 | AH38: =if($K38=$F$4,AH$3,0) -> 0
F39: 34 | G39: =sumif($C$6:$C77,F39,$D$6:$D77) -> 0 | H39: =H38-I39+G39 -> 67420 | I39: =sum(L39:AH39) -> 0 | K39: 34 | L39: =if((L3-L6-L7-L8-L9-L10-L11-L12-L13-L14-L15-L16-L17-L18-L19-L20-L21-L22-L23-L24-L25-L26-L27-L28-L29-L30-L31-L32-L33-L34-L35-L36-L37-L38)>0.1,L38,0) -> 0 | O39: 0 | P39: 0 | S39: 0 | T39: 0 | U39: 0 | V39: 0 | W39: 0 | AA39: =if($K39=$F$4,AA$3,0) -> 0 | AB39: =if($K39=$F$4,AB$3,0) -> 0 | AC39: =if($K39=$F$4,AC$3,0) -> 0 | AD39: =if($K39=$F$4,AD$3,0) -> 0 | AE39: =if($K39=$F$4,AE$3,0) -> 0 | AF39: =if($K39=$F$4,AF$3,0) -> 0 | AG39: =if($K39=$F$4,AG$3,0) -> 0 | AH39: =if($K39=$F$4,AH$3,0) -> 0
F40: 35 | G40: =sumif($C$6:$C78,F40,$D$6:$D78) -> 0 | H40: =H39-I40+G40 -> 67420 | I40: =sum(L40:AH40) -> 0 | K40: 35 | L40: =if((L3-L6-L7-L8-L9-L10-L11-L12-L13-L14-L15-L16-L17-L18-L19-L20-L21-L22-L23-L24-L25-L26-L27-L28-L29-L30-L31-L32-L33-L34-L35-L36-L37-L38-L39)>0.1,L39,0) -> 0 | O40: 0 | P40: 0 | S40: 0 | T40: 0 | U40: 0 | V40: 0 | W40: 0 | AA40: =if($K40=$F$4,AA$3,0) -> 0 | AB40: =if($K40=$F$4,AB$3,0) -> 0 | AC40: =if($K40=$F$4,AC$3,0) -> 0 | AD40: =if($K40=$F$4,AD$3,0) -> 0 | AE40: =if($K40=$F$4,AE$3,0) -> 0 | AF40: =if($K40=$F$4,AF$3,0) -> 0 | AG40: =if($K40=$F$4,AG$3,0) -> 0 | AH40: =if($K40=$F$4,AH$3,0) -> 0
...

Sheet Buy & Hold
B2: Easy Enough: Just fill in all the blue cells while reviewing a property and the results will populate throughout the sheet!
Y4: Rent Growth Calculator
B5: Sale Price | C5: 210000 | E5: Tax Value | F5: 210000 | H5: Current Pro Forma Analysis | N5: 5 Year Debt Paydown Summary | R5: Does it qualify for a commercial loan? | Y5: Rent Growth Rate: | Z5: 0.035
H6: CUURENT RATE ANALYSIS | R6: Debt Coverage Ratio Required: | T6: 1.25 | Y6: Market Rent (Year 1): | Z6: =F29 -> 3000
B7: Unit Breakdown | H7: Item | I7: $/Mo. | K7: Mortgage Calculator | O7: Year | P7: Figure
B8: Unit # | C8: #Beds | D8: #Baths | E8: Rent/Mo | F8: Market Rent | H8: Gross Rents | I8: =E29 -> 2000 | K8: Sale Price | L8: =C5 -> 210000 | N8: Total Debt Paydown | O8: 1 | P8: =($L$15*12)-P26 -> 2111.8686 | T8: Assumption | U8: Pro Forma | V8: Actual | Y8: End of Year: | Z8: Market Rent
B9: 1 | C9: 3 | D9: 2.5 | E9: 2000 | F9: 3000 | H9: Property Management | I9: =C$40*I8 -> 0 | K9: Loan to Value Ratio | L9: =1-E$33 -> 0.99 | N9: ROI on Paydown | O9: 1 | P9: =((P8)/$L$10) -> 1.0056517 | R9: Gross Rents | U9: =I8*12 -> 24000 | V9: =I23*12 -> 36000 | Y9: 1 | Z9: =Z$6*((1+Z$5)^(Y9-1)) -> 3000
B10: 2 | C10: 3 | D10: 3 | E10: 0 | F10: 0 | H10: Property Taxes | I10: =C$33/12 -> 116.66667 | K10: Down Payment | L10: =E33*C5 -> 2100 | N10: Total Debt Paydown | O10: 2 | P10: =($L$15*12)-P29 -> 2264.5358 | R10: Vacancy | T10: =C41 -> 0 | U10: =U9*T10 -> 0 | V10: =I13*12 -> 0 | Y10: 2 | Z10: =Z$6*((1+Z$5)^(Y10-1)) -> 3105
B11: 3 | C11: 3 | D11: 3 | E11: 0 | F11: 0 | H11: Insurance | I11: =C34 -> 100 | K11: Closing Costs | L11: =E$36 -> 2100 | N11: ROI on Paydown | O11: 2 | P11: =((P10)/$L$10) -> 1.0783504 | R11: Prop Mgmt | T11: =C40 -> 0 | U11: =U9*T11 -> 0 | V11: =12*I9 -> 0 | Y11: 3 | Z11: =Z$6*((1+Z$5)^(Y11-1)) -> 3213.675
B12: 4 | C12: 3 | D12: 3 | E12: 0 | F12: 0 | H12: Owner-Paid Utilities | I12: =SUM(C$35:C$39) -> 0 | K12: Principal | L12: =L8*L9 -> 207900 | N12: Total Debt Paydown | O12: 3 | P12: =($L$15*12)-P32 -> 2428.2393 | R12: Cash Reserves | T12: 0 | U12: =T12*U9 -> 0 | V12: =T12*V9 -> 0 | Y12: 4 | Z12: =Z$6*((1+Z$5)^(Y12-1)) -> 3326.1536
